Workbook

Sheet 使い方
A1: 使い方：カンツギ 事業計画書「計算詳細版」の数字の裏取り
A2: このブックは、計算詳細版の数字が計算モデル（deck/tora_v2.js）と同じ式で出ることを、すべての計算過程が追える形で示すためのもの。入力は「前提」だけにあり、他のシートはすべて式。最後の「照合」で、Excel の結果と tora_v2.js の値が一致することを確かめている。
A4: シートの一覧
A5: シート | B5: 中身 | C5: 計算詳細版のページ | D5: tora_v2.js の対応
A6: 前提 | B6: 入力をすべて集めた（青字）。確度と出典を付けた。年ごとの項目は1〜10年目 | C6: p.4・16・17・32 | D6: WAGE・PLAN・SAVE・CLOUD・SETUP_TASKS・ROLES・EXT・GROWTH・LOAD・RECRUIT_RATE・ADVISORS
A7: 時給 | B7: 職長・施工管理者の1時間の人件費＝年収×会社負担÷年間総実労働時間 | C7: p.5 | D7: H（hourly）
A8: お客様の効果 | B8: 1台1日の効果、年の効果、支払い、倍率、元が取れる分、感度表、手戻り（参考） | C8: p.6・7・8 | D8: customerValue()
A9: 値段と原価 | B9: 1拠点の売上、1台の原価の内訳と検算、粗利率、広い原価の粗利率、台数と使い方、追加料金の案 | C9: p.9・10・11・12 | D9: priceSite・CLOUD・cloudPerDevice・cogsSite・marginSite
A10: 導入支援 | B10: 6つの作業×人日、日額、原価・値段・粗利、お客様の1年目の支払い | C10: p.13 | D10: SETUP_TASKS・setupDays・CSDAY・setupTravel
A11: 体制と人件費 | B11: 8つの役割の年収×人数、人件費、採用費、つまみの反映、導入コンサルタントの上限 | C11: p.17 | D11: ROLES・EXT.heads・team()
A12: 拠点と売上 | B12: 期首・解約・新規・期末、既存と新規の利用料、導入支援、個社設定、売上 | C12: p.14・15 | D12: run() の拠点と売上
A13: 損益と現金 | B13: 原価、粗利、販管費、営業利益、累計、現金。黒字化の年・累計回収の年・最低の現金 | C13: p.3・18・30 | D13: run() の損益と現金
A14: 黒字ライン | B14: 損益分岐点売上、社員1人あたりの拠点、黒字に必要な拠点、5年目に要る台数 | C14: p.19・22 | D14: run() の bep・sitesPerStaff
A15: LTV・CAC | B15: LTV（3・5・7・10年）、CAC、回収月数 | C15: p.20 | D15: unit()
A16: 崩れたとき | B16: 前提を一つずつ崩した結果（tora_v2.js の値を貼った）と、Excel で再現する方法 | C16: p.21・22 | D16: run(o)・shortfall()
... A19: 照合 | B19: Excel の主な結果と tora_v2.js の値を並べ、差がゼロ（丸め誤差）であることを示す | C19: ─ | D19: node で出した値
A21: 色の見方
A22: 青字 | B22: 入力。前提シートだけにある。ここを書き換えると全部のシートが計算し直される
A23: 黒字 | B23: 計算（式）
A24: 赤字（▲） | B24: マイナスの数字（赤字の金額など）
A25: 緑字 | B25: 黒字化の年。損益と現金の営業利益の行では、初めて黒字になる年を緑で示す
A26: 灰色の数字 | B26: tora_v2.js を node で計算して貼った値（崩れたとき・照合の数字の列）。式ではない
A27: 紺の行 | B27: 見出し
A29: 確度の見方（前提シートの「確度」の列）
A30: 統計 | B30: 国の統計（賃金構造基本統計調査、毎月勤労統計調査、建設業許可業者数調査など）
A31: 制度 | B31: 法律や保険料率など、制度で決まる値（社会保険料の会社負担、残業の割増）
A32: 公表 | B32: メーカー・クラウド・AIの公表価格
A33: 見積 | B33: 社内の見積（値段、台数、人数、年収、経費など）
A34: 仮説 | B34: 実証で測るもの（削減時間、手戻りの削減、会える率・成約率など）
A35: 仮定 | B35: 計算のために置いた値（為替、シナリオのつまみ、参考の表の軸など）
A36: 換算 | B36: 単位の換算（60分＝1時間など）。前提ではないが、式の中に数字を書かないために置いた
A38: 決まりと注意
A39: ・金額は、ことわりがなければ万円。各行に単位を書き、右の列に式（言葉）を書いた。
A40: ・前提のつまみ（8-1〜8-6）が初期値のとき、tora_v2.js の計画（run({years:10})）と一致する。5年目までの値は run()（5年）と同じ。
A41: ・つまみを変えれば、崩れたときのシナリオを Excel で再現できる（崩れたときシートの右の列）。
A42: ・このモデルは運転資本・税・償却を含まない簡易計算。
A43: ・元のファイル：deck/tora_v2.js（計算モデル）、deck/tora_market.js（市場規模）、deck/build_tora_detail.js（計算詳細版の作り）。モデルと資料のファイルは書き換えていない。
A44: ・フォントは BIZ UDPゴシック を指定している（無い環境では別のフォントで表示される）。PDF は BIZ UDPゴシック の無い環境で書き出したので IPA Pゴシック で表示している。

Sheet 前提
A1: 前提：入力はこのシートだけ
A2: 青字＝入力（ここだけを書き換える）、黒字＝計算。他のシートはすべてこのシートを参照する式。年ごとの項目は「値」の列が1年目で、右へ2〜10年目。1〜5年目は tora_v2.js の ROLES・GROWTH、6〜10年目は EXT の値。確度：統計＝公的統計／制度＝法律・料率など制度で決まる値／公表＝メーカー・クラウドの公表価格／見積＝社内見積／仮説＝実証で測る／仮定＝計算のために置いた値／換算＝単位の換算。
A3: 番号 | B3: 項目 | C3: 単位 | D3: 確度 | E3: 値（年ごとは1年目） | F3: 2年目 | G3: 3年目 | H3: 4年目 | I3: 5年目 | J3: 6年目 | K3: 7年目 | L3: 8年目 | M3: 9年目 | N3: 10年目 | O3: 出典・メモ
A4: 0. 単位の換算（前提ではなく、式の中に数字を書かないために置く）
A5: 0-1 | B5: 1時間の分 | C5: 分/時間 | D5: 換算 | E5: 60
A6: 0-2 | B6: 1年の月数 | C6: か月/年 | D6: 換算 | E6: 12
A7: 0-3 | B7: 1万円の円 | C7: 円/万円 | D7: 換算 | E7: 10000
A8: 0-4 | B8: 1年の日数 | C8: 日/年 | D8: 換算 | E8: 365
A9: 0-5 | B9: 1億円の万円 | C9: 万円/億円 | D9: 換算 | E9: 10000
A10: 0-6 | B10: AIの単価の基準（100万トークン） | C10: トークン | D10: 換算 | E10: 1000000 | O10: AIの単価は100万トークンあたりのドルで書く
A11: 1. 時給（お客様の1時間の人件費）
A12: 1-1 | B12: 職長（電気工事従事者）の年収 | C12: 万円/年 | D12: 統計 | E12: 551 | O12: 厚生労働省「賃金構造基本統計調査」令和5年 電気工事従事者：きまって支給する給与 月36.74万円×12＋賞与等110.06万円＝550.94万円（残業代を含む）。令和6年も約548〜551万円
A13: 1-2 | B13: 施工管理者の年収 | C13: 万円/年 | D13: 統計 | E13: 620 | O13: 同調査で代用：建築技術者 約642万円（令和6年）と土木技術者 約604万円（令和5年）の間。施工管理技士は標本が少ないので使わない
A14: 1-3 | B14: 会社負担（社会保険料）を含める倍率 | C14: 倍 | D14: 制度 | E14: 1.17 | O14: 会社負担 約17%：健康保険 約5.0%＋厚生年金9.15%＋雇用保険（建設）1.1%＋子ども・子育て拠出金0.36%＋労災 約1.2%
A15: 1-4 | B15: 建設業の月の総実労働時間（残業を含む） | C15: 時間/月 | D15: 統計 | E15: 161.5 | O15: 厚生労働省「毎月勤労統計調査」令和6年 建設業の総実労働時間（所定内＋所定外）
A16: 1-5 | B16: 年間総実労働時間 | C16: 時間/年 | D16: 統計 | E16: =E15*$E$6 -> 1938 | O16: 月161.5時間×12＝1,938時間（tora_v2.js の annualHours）
A17: 1-6 | B17: 残業の割増 | C17: 倍 | D17: 制度 | E17: 1.25 | O17: 労働基準法：時間外労働は25%以上の割増。参考の計算だけに使い、計画には入れない
A18: 1-7 | B18: 参考：所定の1日の時間 | C18: 時間/日 | D18: 仮定 | E18: 8 | O18: 所定の目安（1日8時間）。参考の比較だけに使う
A19: 1-8 | B19: 参考：所定の年の日数（目安） | C19: 日/年 | D19: 仮定 | E19: 244 | O19: 所定の目安（年約244日）。8時間×244日＝1,952時間は所定の目安で、実績ではない
A20: 2. 端末と値段（1拠点）
A21: 2-1 | B21: 1拠点の台数 | C21: 台/拠点 | D21: 見積 | E21: 10 | O21: 1班に1台、職長が掛ける。5現場×2班（計算詳細版 p.10）
A22: 2-2 | B22: 端末を使う日数 | C22: 日/年 | D22: 見積 | E22: 240 | O22: 上限に近い想定。現場の稼働日数で減る
A23: 2-3 | B23: 基盤の利用料 | C23: 万円/年/拠点 | D23: 見積 | E23: 60 | O23: 月5万円×12
A24: 2-4 | B24: 端末ライセンス | C24: 万円/年/台 | D24: 見積 | E24: 24 | O24: 月2万円×12。録画は端末に無制限、AIで解析する場面に月の上限
A25: 2-5 | B25: 導入支援（初年度のみ） | C25: 万円/拠点 | D25: 見積 | E25: 200 | O25: 42人日の原価141万円の約1.4倍（他社の相場は未確認）
A26: 2-6 | B26: カメラ付きAIグラスの本体 | C26: 万円/台 | D26: 公表 | E26: 8 | O26: Ray-Ban Meta 7.4〜8.9万円
A27: 2-7 | B27: 表示付きARグラスの本体 | C27: 万円/台 | D27: 公表 | E27: 12 | O27: Meta Ray-Ban Display $799
A28: 2-8 | B28: リースの月額料率（3年リース） | C28: 割合/月 | D28: 見積 | E28: 0.03 | O28: 3年リースの料率 約3%／月。リース会社の見積で確認する
A29: 2-9 | B29: 構成：カメラ付きAIグラス | C29: 台/拠点 | D29: 見積 | E29: 8 | O29: 記録用
A30: 2-10 | B30: 構成：表示付きARグラス | C30: 台/拠点 | D30: 見積 | E30: 2 | O30: 手元に図面を出す班
A31: 2-11 | B31: リースの年額：カメラ付き | C31: 万円/年/台 | D31: 公表 | E31: =$E$26*$E$28*$E$6 -> 2.88 | O31: 本体8万円×月額料率3%×12か月
A32: 2-12 | B32: リースの年額：表示付き | C32: 万円/年/台 | D32: 公表 | E32: =$E$27*$E$28*$E$6 -> 4.32 | O32: 本体12万円×月額料率3%×12か月
A33: 2-13 | B33: 構成の台数の合計（確認） | C33: 台/拠点 | D33: 見積 | E33: =$E$29+$E$30 -> 10 | O33: 2-1の台数と同じであること。リースはお客様の支払いだけに効き、当社の売上・原価には入らない
A34: 3. 削減時間（1台1日）と手戻り（参考）
A35: 3-1 | B35: 職長の削減（日報・撮影・黒板） | C35: 分/台/日 | D35: 仮説 | E35: 15 | O35: 実証で導入前2週間と導入後4週間を比べて測る
A36: 3-2 | B36: 施工管理者の削減（写真整理・写真台帳） | C36: 分/台/日 | D36: 仮説 | E36: 20 | O36: 同上
A37: 3-3 | B37: 参考：お客様の完成工事高 | C37: 万円/年 | D37: 仮定 | E37: 300000 | O37: 中堅100人規模の目安30億円。計画に入れない
A38: 3-4 | B38: 参考：手戻りが工事費に占める割合 | C38: 割合 | D38: 仮定 | E38: 0.02 | O38: 海外研究の範囲0.4〜6%、RC造の事例1.85〜2.1%から控えめに
A39: 3-5 | B39: 参考：ARが効く対象工種の割合 | C39: 割合 | D39: 仮説 | E39: 0.3
A40: 3-6 | B40: 参考：手戻りの削減率 | C40: 割合 | D40: 仮説 | E40: 0.2
...

Sheet 時給
A1: 時給：お客様の1時間の人件費
A2: 1時間の人件費＝年収×会社負担÷年間総実労働時間。年収も総実労働時間も残業を含むので、分子と分母がそろっている（計算詳細版 p.5）。
A3: 項目 | B3: 職長（電工） | C3: 施工管理者 | D3: 単位 | E3: 式（言葉）
A4: 年収（残業代・賞与を含む） | B4: ='前提'!$E$12 -> 551 | C4: ='前提'!$E$13 -> 620 | D4: 万円/年 | E4: 賃金構造基本統計調査（前提1-1・1-2）
A5: 会社負担を含める倍率 | B5: ='前提'!$E$14 -> 1.17 | C5: ='前提'!$E$14 -> 1.17 | D5: 倍 | E5: 社会保険料の会社負担 約17%（前提1-3）
A6: 会社負担込みの年の人件費 | B6: =$B$4*$B$5 -> 644.67 | C6: =$C$4*$C$5 -> 725.4 | D6: 万円/年 | E6: 年収×会社負担
A7: 年間総実労働時間（残業を含む） | B7: ='前提'!$E$16 -> 1938 | C7: ='前提'!$E$16 -> 1938 | D7: 時間/年 | E7: 毎月勤労統計 建設業 月161.5時間×12（前提1-5）
A8: 1時間の人件費 | B8: =$B$6/$B$7 -> 0.33264706 | C8: =$C$6/$C$7 -> 0.37430341 | D8: 万円/時間 | E8: 年収×会社負担÷年間総実労働時間
A9: 1時間の人件費（円） | B9: =$B$8*'前提'!$E$7 -> 3326.4706 | C9: =$C$8*'前提'!$E$7 -> 3743.0341 | D9: 円/時間 | E9: 上の万円×10,000
A10: 1分の人件費 | B10: =$B$9/'前提'!$E$5 -> 55.441176 | C10: =$C$9/'前提'!$E$5 -> 62.383901 | D10: 円/分 | E10: 1時間の人件費÷60
A11: 参考（計画には入れない）
A12: 削った時間がすべて残業だった場合の1時間の価値 | B12: =$B$9*'前提'!$E$17 -> 4158.0882 | C12: =$C$9*'前提'!$E$17 -> 4678.7926 | D12: 円/時間 | E12: 1時間の人件費×残業の割増1.25
A13: そのときのお客様の効果（1拠点） | B13: ='お客様の効果'!$C$14*'前提'!$E$17 -> 623.7887 | D13: 万円/年 | E13: お客様の効果（年約499万円）×1.25。計画には入れない
A14: 参考：所定の目安の時間（1日8時間×244日） | B14: ='前提'!$E$18*'前提'!$E$19 -> 1952 | C14: ='前提'!$E$18*'前提'!$E$19 -> 1952 | D14: 時間/年 | E14: 1日8時間×約244日。所定の目安で、実績ではない
A15: 参考：所定の目安で割った1時間 | B15: =$B$6/$B$14*'前提'!$E$7 -> 3302.6127 | C15: =$C$6/$C$14*'前提'!$E$7 -> 3716.1885 | D15: 円/時間 | E15: 年収×会社負担÷1,952時間。値は近いが意味が違うので使わない
A17: 注1：総実労働時間は毎月勤労統計の「総実労働時間」で、所定外（残業）を含む実績。
A18: 注2：年収（賃金構造基本統計調査）も、きまって支給する給与（残業代を含む）と賞与の合計。分子にも分母にも残業が入っている。
A19: 注3：残業を除いた所定内の時間で割ると、分母だけが小さくなり単価が高く出るので使わない。「1日8時間×約244日＝1,952時間」は所定の目安で実績ではない（値は1,938時間に近いが意味が違う）。
A20: 注4：削った時間がすべて残業なら、割増1.25倍の分だけ効果は大きくなる（年約624万円）。計画には入れない。お客様の効果は控えめに見ている。当社の売上と利益は、この単価には左右されない。

Sheet お客様の効果
A1: お客様の効果：1拠点10台で年約499万円、支払いの約1.5倍
A2: 効果はAIグラスを掛けた班の分だけで数える（社員全員が減るとは数えない）。お客様の支払いは当社への利用料とグラスのリース。tora_v2.js の customerValue() と同じ式（計算詳細版 p.6〜8）。
A3: 項目 | B3: 単位 | C3: 値 | F3: 式（言葉）
A4: 1台1日の効果
A5: 職長の削減 | B5: 分/台/日 | C5: ='前提'!$E$35 -> 15 | D5: 日報・撮影・黒板（前提3-1・仮説）
A6: 施工管理者の削減 | B6: 分/台/日 | C6: ='前提'!$E$36 -> 20 | D6: 写真整理・写真台帳（前提3-2・仮説）
A7: 職長の1時間の人件費 | B7: 円/時間 | C7: ='時給'!$B$9 -> 3326.4706 | D7: 時給シート
A8: 施工管理者の1時間の人件費 | B8: 円/時間 | C8: ='時給'!$C$9 -> 3743.0341 | D8: 時給シート
A9: 1台1日の効果 | B9: 円/台/日 | C9: =$C$5/'前提'!$E$5*$C$7+$C$6/'前提'!$E$5*$C$8 -> 2079.2957 | D9: 15分÷60×職長の時給＋20分÷60×施工管理者の時給
A10: 1台1日の効果（万円） | B10: 万円/台/日 | C10: =$C$9/'前提'!$E$7 -> 0.20792957 | D10: 上の円÷10,000
A11: 1拠点・1年の効果
A12: 1拠点の台数 | B12: 台/拠点 | C12: ='前提'!$E$21 -> 10 | D12: 前提2-1
A13: 端末を使う日数 | B13: 日/年 | C13: ='前提'!$E$22 -> 240 | D13: 前提2-2。上限に近い想定
A14: お客様の効果（年） | B14: 万円/年 | C14: =$C$10*$C$12*$C$13 -> 499.03096 | D14: 1台1日の効果×台数×日数
A15: 1台1日の削減の合計 | B15: 分/台/日 | C15: =$C$5+$C$6 -> 35 | D15: 職長15分＋施工管理者20分
A16: 浮く時間（分） | B16: 分/年 | C16: =$C$15*$C$12*$C$13 -> 84000 | D16: 35分×10台×240日
A17: 浮く時間（時間） | B17: 時間/年 | C17: =$C$16/'前提'!$E$5 -> 1400 | D17: 上の分÷60
A18: お客様の支払い（1拠点・2年目以降の年額）
A19: 当社：基盤 | B19: 万円/年 | C19: ='値段と原価'!$C$5 -> 60 | D19: 月5万円×12（値段と原価。値段の倍率を反映）
A20: 当社：端末ライセンス×台数 | B20: 万円/年 | C20: ='値段と原価'!$C$6*$C$12 -> 240 | D20: 月2万円×12×10台
A21: 当社への利用料 | B21: 万円/年 | C21: =$C$19+$C$20 -> 300 | D21: 基盤＋端末ライセンス
A22: リース：カメラ付きAIグラス | B22: 万円/年 | C22: ='前提'!$E$29*'前提'!$E$31 -> 23.04 | D22: 8台×(8万円×3%×12)
A23: リース：表示付きARグラス | B23: 万円/年 | C23: ='前提'!$E$30*'前提'!$E$32 -> 8.64 | D23: 2台×(12万円×3%×12)
A24: リースの合計 | B24: 万円/年 | C24: =$C$22+$C$23 -> 31.68 | D24: お客様からリース会社へ払う（当社の売上ではない）
A25: お客様の支払いの合計 | B25: 万円/年 | C25: =$C$21+$C$24 -> 331.68 | D25: 利用料＋リース
A26: 倍率（効果÷支払い） | B26: 倍 | C26: =$C$14/$C$25 -> 1.5045555 | D26: お客様の効果÷支払いの合計
A27: 元が取れる分（1台1日に何分減れば支払いと同じになるか）
A28: 1台1日の支払い | B28: 円/台/日 | C28: =$C$25/($C$12*$C$13)*'前提'!$E$7 -> 1382 | D28: 支払い÷(台数×日数)
A29: 同じ配分での1分の人件費 | B29: 円/分 | C29: =($C$7*$C$5/$C$15+$C$8*$C$6/$C$15)/'前提'!$E$5 -> 59.408448 | D29: (職長の時給×15/35＋施工管理者の時給×20/35)÷60
A30: 元が取れる分 | B30: 分/台/日 | C30: =$C$28/$C$29 -> 23.262685 | D30: 1台1日の支払い÷同じ配分での1分の人件費
A31: 感度表：使う日数×1台1日の削減
A32: 年の効果 使う日数＼1台1日の削減（職長＋施工管理） | B32: 単位 | C32: =TEXT('前提'!$E$43+'前提'!$E$44,"0")&"分"&CHAR(10)&"（"&'前提'!$E$43&"＋"&'前提'!$E$44&"）" -> 25分 （10＋15） | D32: =TEXT('前提'!$F$43+'前提'!$F$44,"0")&"分"&CHAR(10)&"（"&'前提'!$F$43&"＋"&'前提'!$F$44&"）" -> 35分 （15＋20） | E32: =TEXT('前提'!$G$43+'前提'!$G$44,"0")&"分"&CHAR(10)&"（"&'前提'!$G$43&"＋"&'前提'!$G$44&"）" -> 60分 （25＋35） | F32: 式（言葉）
A33: ='前提'!$E$42 -> 180 | B33: 万円/年 | C33: =('前提'!$E$43/'前提'!$E$5*$C$7+'前提'!$E$44/'前提'!$E$5*$C$8)/'前提'!$E$7*$C$12*'前提'!$E$42 -> 268.23065 | D33: =('前提'!$F$43/'前提'!$E$5*$C$7+'前提'!$F$44/'前提'!$E$5*$C$8)/'前提'!$E$7*$C$12*'前提'!$E$42 -> 374.27322 | E33: =('前提'!$G$43/'前提'!$E$5*$C$7+'前提'!$G$44/'前提'!$E$5*$C$8)/'前提'!$E$7*$C$12*'前提'!$E$42 -> 642.50387 | F33: (分÷60×時給)の合計×台数×日数÷10,000
A34: ='前提'!$F$42 -> 200 | B34: 万円/年 | C34: =('前提'!$E$43/'前提'!$E$5*$C$7+'前提'!$E$44/'前提'!$E$5*$C$8)/'前提'!$E$7*$C$12*'前提'!$F$42 -> 298.03406 | D34: =('前提'!$F$43/'前提'!$E$5*$C$7+'前提'!$F$44/'前提'!$E$5*$C$8)/'前提'!$E$7*$C$12*'前提'!$F$42 -> 415.85913 | E34: =('前提'!$G$43/'前提'!$E$5*$C$7+'前提'!$G$44/'前提'!$E$5*$C$8)/'前提'!$E$7*$C$12*'前提'!$F$42 -> 713.89319 | F34: (分÷60×時給)の合計×台数×日数÷10,000
A35: ='前提'!$G$42 -> 220 | B35: 万円/年 | C35: =('前提'!$E$43/'前提'!$E$5*$C$7+'前提'!$E$44/'前提'!$E$5*$C$8)/'前提'!$E$7*$C$12*'前提'!$G$42 -> 327.83746 | D35: =('前提'!$F$43/'前提'!$E$5*$C$7+'前提'!$F$44/'前提'!$E$5*$C$8)/'前提'!$E$7*$C$12*'前提'!$G$42 -> 457.44505 | E35: =('前提'!$G$43/'前提'!$E$5*$C$7+'前提'!$G$44/'前提'!$E$5*$C$8)/'前提'!$E$7*$C$12*'前提'!$G$42 -> 785.28251 | F35: (分÷60×時給)の合計×台数×日数÷10,000
A36: ='前提'!$H$42 -> 240 | B36: 万円/年 | C36: =('前提'!$E$43/'前提'!$E$5*$C$7+'前提'!$E$44/'前提'!$E$5*$C$8)/'前提'!$E$7*$C$12*'前提'!$H$42 -> 357.64087 | D36: =('前提'!$F$43/'前提'!$E$5*$C$7+'前提'!$F$44/'前提'!$E$5*$C$8)/'前提'!$E$7*$C$12*'前提'!$H$42 -> 499.03096 | E36: =('前提'!$G$43/'前提'!$E$5*$C$7+'前提'!$G$44/'前提'!$E$5*$C$8)/'前提'!$E$7*$C$12*'前提'!$H$42 -> 856.67183 | F36: (分÷60×時給)の合計×台数×日数÷10,000
A37: 倍率 使う日数＼1台1日の削減（職長＋施工管理） | B37: 単位 | C37: =TEXT('前提'!$E$43+'前提'!$E$44,"0")&"分"&CHAR(10)&"（"&'前提'!$E$43&"＋"&'前提'!$E$44&"）" -> 25分 （10＋15） | D37: =TEXT('前提'!$F$43+'前提'!$F$44,"0")&"分"&CHAR(10)&"（"&'前提'!$F$43&"＋"&'前提'!$F$44&"）" -> 35分 （15＋20） | E37: =TEXT('前提'!$G$43+'前提'!$G$44,"0")&"分"&CHAR(10)&"（"&'前提'!$G$43&"＋"&'前提'!$G$44&"）" -> 60分 （25＋35） | F37: 式（言葉）
A38: ='前提'!$E$42 -> 180 | B38: 倍 | C38: ='お客様の効果'!$C$33/$C$25 -> 0.80870312 | D38: ='お客様の効果'!$D$33/$C$25 -> 1.1284166 | E38: ='お客様の効果'!$E$33/$C$25 -> 1.9371197 | F38: 年の効果÷お客様の支払い（331.68万円）
A39: ='前提'!$F$42 -> 200 | B39: 倍 | C39: ='お客様の効果'!$C$34/$C$25 -> 0.89855902 | D39: ='お客様の効果'!$D$34/$C$25 -> 1.2537962 | E39: ='お客様の効果'!$E$34/$C$25 -> 2.1523552 | F39: 年の効果÷お客様の支払い（331.68万円）
A40: ='前提'!$G$42 -> 220 | B40: 倍 | C40: ='お客様の効果'!$C$35/$C$25 -> 0.98841492 | D40: ='お客様の効果'!$D$35/$C$25 -> 1.3791759 | E40: ='お客様の効果'!$E$35/$C$25 -> 2.3675908 | F40: 年の効果÷お客様の支払い（331.68万円）
...

Sheet 値段と原価
A1: 値段と原価：1拠点300万円、原価84万円、粗利216万円（72%）
A2: 1台の原価は、クラウド・AIの公表単価から積み上げて検算した。計画の数字は tora_v2.js の CLOUD の値（モデルの値）を使い、検算の値と並べる（計算詳細版 p.9〜12）。
A3: 項目 | B3: 単位 | C3: 値 | F3: 式（言葉）
A4: 1拠点の売上（年）
A5: 基盤（値段の倍率を反映） | B5: 万円/年/拠点 | C5: ='前提'!$E$23*'前提'!$E$139 -> 60 | D5: 月5万円×12×値段の倍率
A6: 端末ライセンス1台（値段の倍率を反映） | B6: 万円/年/台 | C6: ='前提'!$E$24*'前提'!$E$139 -> 24 | D6: 月2万円×12×値段の倍率
A7: 1拠点の台数 | B7: 台/拠点 | C7: ='前提'!$E$21 -> 10 | D7: 前提2-1
A8: 1拠点の利用料 | B8: 万円/年/拠点 | C8: =$C$5+$C$6*$C$7 -> 300 | D8: 基盤60＋端末24×10台
A9: 参考：値段の倍率を掛ける前の1拠点の利用料 | B9: 万円/年/拠点 | C9: ='前提'!$E$23+'前提'!$E$24*$C$7 -> 300 | D9: 市場規模の計算に使う
A10: 1拠点の原価と粗利（年）
A11: 1台の原価（年） | B11: 万円/年/台 | C11: ='値段と原価'!$D$41*'前提'!$E$6/'前提'!$E$7 -> 7.2 | D11: 6,000円×12か月÷10,000（6,000円は下の内訳の合計）
A12: 1台の原価（原価の倍率を反映） | B12: 万円/年/台 | C12: =$C$11*'前提'!$E$141 -> 7.2 | D12: 1台の原価×原価の倍率（前提8-3）
A13: データ基盤 | B13: 万円/年/拠点 | C13: ='前提'!$E$74 -> 12 | D13: 月1万円×12
A14: 1拠点の原価 | B14: 万円/年/拠点 | C14: =$C$13+$C$12*$C$7 -> 84 | D14: データ基盤12＋1台7.2×10台
A15: 1拠点の粗利 | B15: 万円/年/拠点 | C15: =$C$8-$C$14 -> 216 | D15: 1拠点の利用料−1拠点の原価
A16: 粗利率（利用料） | B16: 割合 | C16: =$C$15/$C$8 -> 0.72 | D16: 1拠点の粗利÷1拠点の利用料
A17: 粗利率と台数・使い方（1拠点）
A18: 台数 | B18: 単位 | C18: 1拠点の利用料 （万円/年） | D18: ="粗利率"&CHAR(10)&"大事な場面だけ"&CHAR(10)&"月"&TEXT('値段と原価'!$D$41,"#,##0")&"円/台" -> 粗利率 大事な場面だけ 月6,000円/台 | E18: ="粗利率"&CHAR(10)&"全編を毎秒解析"&CHAR(10)&"月"&TEXT('前提'!$E$72,"#,##0")&"円/台" -> 粗利率 全編を毎秒解析 月50,000円/台 | F18: 式（言葉）
A19: ='前提'!$E$80 -> 5 | B19: 万円/年・割合 | C19: =$C$5+$C$6*'前提'!$E$80 -> 180 | D19: =1-($C$13+$C$12*'前提'!$E$80)/($C$5+$C$6*'前提'!$E$80) -> 0.73333333 | E19: =1-($C$13+'前提'!$E$72*'前提'!$E$6/'前提'!$E$7*'前提'!$E$80)/($C$5+$C$6*'前提'!$E$80) -> -0.73333333 | F19: 1−(データ基盤＋1台の原価×台数)÷(基盤＋端末×台数)
A20: ='前提'!$F$80 -> 10 | B20: 万円/年・割合 | C20: =$C$5+$C$6*'前提'!$F$80 -> 300 | D20: =1-($C$13+$C$12*'前提'!$F$80)/($C$5+$C$6*'前提'!$F$80) -> 0.72 | E20: =1-($C$13+'前提'!$E$72*'前提'!$E$6/'前提'!$E$7*'前提'!$F$80)/($C$5+$C$6*'前提'!$F$80) -> -1.04 | F20: 1−(データ基盤＋1台の原価×台数)÷(基盤＋端末×台数)
A21: ='前提'!$G$80 -> 25 | B21: 万円/年・割合 | C21: =$C$5+$C$6*'前提'!$G$80 -> 660 | D21: =1-($C$13+$C$12*'前提'!$G$80)/($C$5+$C$6*'前提'!$G$80) -> 0.70909091 | E21: =1-($C$13+'前提'!$E$72*'前提'!$E$6/'前提'!$E$7*'前提'!$G$80)/($C$5+$C$6*'前提'!$G$80) -> -1.2909091 | F21: 1−(データ基盤＋1台の原価×台数)÷(基盤＋端末×台数)
A22: 注：1台の値段（月2万円）が1台の原価（月0.6万円）を賄うので、台数が増えても粗利率はほぼ同じ。全編を送ると台数が増えるほど赤字が膨らむ。
A23: 1台の原価の内訳（円/台/月）
A24: 項目 | B24: 単位 | C24: 検算の値 | D24: モデルの値 （tora_v2.js） | E24: 差 モデル−検算 | F24: 式（言葉）
A25: 音声：録画の分数 | B25: 分/台/月 | C25: ='前提'!$E$47*'前提'!$E$48*'前提'!$E$5 -> 4800 | F25: 1日4時間×月20日×60分＝80時間
A26: 音声の文字起こし | B26: 円/台/月 | C26: =$C$25*'前提'!$E$49*'前提'!$E$46 -> 2160 | D26: ='前提'!$E$67 -> 2200 | E26: =$D$26-$C$26 -> 40 | F26: 4,800分×$0.003×150円。削減時間（35分）とは関係なく、録画した時間に掛かる
A27: 画像：1枚の画像のトークン | B27: トークン/枚 | C27: ='前提'!$E$52*'前提'!$E$53/'前提'!$E$54 -> 1228.8 | F27: 1280×720÷750
A28: 画像：1枚の入力トークン | B28: トークン/枚 | C28: =$C$27+'前提'!$E$55 -> 1528.8 | F28: 画像＋指示文300
A29: 画像解析 Claude Haiku 5.5：1枚 | B29: 円/枚 | C29: =($C$28*'前提'!$E$57+'前提'!$E$56*'前提'!$E$58)/'前提'!$E$10*'前提'!$E$46 -> 0.034182 | F29: (入力×$0.10＋出力150×$0.50)÷100万×150円
A30: 画像解析 Claude Haiku 5.5：月 | B30: 円/台/月 | C30: =$C$29*'前提'!$E$50 -> 102.546 | F30: 1枚×3,000枚
A31: 画像解析 Claude Sonnet 5.5：1枚 | B31: 円/枚 | C31: =($C$28*'前提'!$E$59+'前提'!$E$56*'前提'!$E$60)/'前提'!$E$10*'前提'!$E$46 -> 0.68364 | F31: (入力×$2＋出力150×$10)÷100万×150円
A32: 画像解析 Claude Sonnet 5.5：月 | B32: 円/台/月 | C32: =$C$31*'前提'!$E$50 -> 2050.92 | F32: 1枚×3,000枚
A33: 画像解析 モデルの置き方：1枚 | B33: 円/枚 | C33: ='前提'!$E$68/'前提'!$E$50 -> 0.33333333 | F33: 月1,000円÷3,000枚（1枚約1,000トークンとして置いた値）
A34: 画像解析（大事な場面 月3,000枚） | B34: 円/台/月 | D34: ='前提'!$E$68 -> 1000 | F34: モデルの1,000円は Haiku 5.5（約100円）と Sonnet 5.5（約2,050円）の間
A35: 全部を Sonnet 5.5 にした場合の増え方 | B35: 円/台/月 | C35: =$C$32-'前提'!$E$68 -> 1050.92 | F35: Sonnet 5.5 の月額−モデルの1,000円
A36: 報告書：1件の費用（Sonnet 5.5） | B36: 円/件 | C36: =('前提'!$E$62*'前提'!$E$59+'前提'!$E$63*'前提'!$E$60)/'前提'!$E$10*'前提'!$E$46 -> 9 | F36: (入力2万×$2＋出力2千×$10)÷100万×150円
A37: 報告書の生成 | B37: 円/台/月 | C37: =$C$36*'前提'!$E$61*'前提'!$E$48 -> 180 | D37: ='前提'!$E$69 -> 200 | E37: =$D$37-$C$37 -> 20 | F37: 1件×1日1件×20日
A38: 保存：3年間の平均の保管量 | B38: GB/台 | C38: ='前提'!$E$64*'前提'!$E$65/2 -> 180 | F38: 月10GB×36か月÷2（直線で増える量の平均）
A39: 動画の保存 | B39: 円/台/月 | C39: =$C$38*'前提'!$E$66*'前提'!$E$46 -> 675 | D39: ='前提'!$E$70 -> 700 | E39: =$D$39-$C$39 -> 25 | F39: 平均180GB×$0.025×150円
A40: 転送・監視・バックアップ・端末管理（MDM）・余裕 | B40: 円/台/月 | D40: ='前提'!$E$71 -> 1900 | F40: 見積（内訳の検算はしていない）
...

Sheet 導入支援
A1: 導入支援：42人日＋交通費で原価141万円、値段200万円、粗利59万円
A2: 導入支援の人件費は原価に振り替える（販管費から引く）。tora_v2.js の SETUP_TASKS・setupDays・CSDAY・setupTravel と同じ（計算詳細版 p.13）。
A3: 項目 | B3: 単位 | C3: 値 | F3: 式（言葉）
A4: 作業と人日（1拠点）
A5: 現状調査・業務の流れの整理 | B5: 人日 | C5: ='前提'!$E$82 -> 5 | D5: 前提5-1
A6: 端末の設定・アカウント・端末管理 | B6: 人日 | C6: ='前提'!$E$83 -> 3 | D6: 前提5-2
A7: 図面・手順・報告書の型の登録 | B7: 人日 | C7: ='前提'!$E$84 -> 10 | D7: 前提5-3
A8: 職長・施工管理者への研修（2回） | B8: 人日 | C8: ='前提'!$E$85 -> 4 | D8: 前提5-4
A9: 現場での立ち会い・初期の手直し（週2日×8週） | B9: 人日 | C9: ='前提'!$E$86 -> 16 | D9: 前提5-5
A10: 導入前後の効果測定レポート | B10: 人日 | C10: ='前提'!$E$87 -> 4 | D10: 前提5-6
A11: 合計（約2か月） | B11: 人日 | C11: =SUM($C$5:$C$10) -> 42 | D11: 6つの作業の合計
A12: 原価と粗利（1拠点）
A13: 導入コンサルタントの年収 | B13: 万円/年 | C13: ='前提'!$E$97 -> 600 | D13: 前提6-5（1年目の値。tora_v2.js は600を直接使う）
A14: 会社負担を含める倍率 | B14: 倍 | C14: ='前提'!$E$109 -> 1.2 | D14: 前提6-17
A15: 年間稼働日 | B15: 日/年 | C15: ='前提'!$E$89 -> 240 | D15: 前提5-8
A16: 1人日の人件費 | B16: 万円/人日 | C16: =$C$13*$C$14/$C$15 -> 3 | D16: 年収600万円×1.2÷240日
A17: 人件費 | B17: 万円/拠点 | C17: =$C$11*$C$16 -> 126 | D17: 42人日×3万円
A18: 交通費 | B18: 万円/拠点 | C18: ='前提'!$E$88 -> 15 | D18: 16回訪問×約1万円
A19: 原価 | B19: 万円/拠点 | C19: =$C$17+$C$18 -> 141 | D19: 人件費＋交通費
A20: 値段 | B20: 万円/拠点 | C20: ='前提'!$E$25 -> 200 | D20: 前提2-5
A21: 粗利 | B21: 万円/拠点 | C21: =$C$20-$C$19 -> 59 | D21: 値段−原価
A22: 粗利率 | B22: 割合 | C22: =$C$21/$C$20 -> 0.295 | D22: 粗利÷値段
A23: お客様の支払い（1拠点）
A24: お客様の1年目の支払い | B24: 万円 | C24: ='お客様の効果'!$C$21+'お客様の効果'!$C$24+$C$20 -> 531.68 | D24: 利用料300＋リース31.68＋導入支援200
A25: お客様の2年目以降の支払い | B25: 万円/年 | C25: ='お客様の効果'!$C$25 -> 331.68 | D25: 利用料300＋リース31.68
A26: そのうち当社の売上（利用料） | B26: 万円/年 | C26: ='お客様の効果'!$C$21 -> 300 | D26: 1年目は導入支援200万円も当社の売上
A27: 注：当社の売上は利用料300万円（初年度は導入支援200万円も）。リース31.7万円はお客様からリース会社へ払うもので、当社の売上ではない。
A28: 注：導入コンサルタント1人が回せる新規拠点は年6（2か月で1拠点）。新規拠点がこの上限内かは「体制と人件費」で確かめる。

Sheet 体制と人件費
A1: 体制と人件費：8つの役割×年収×人数。5年目は23人
A2: 人件費＝年収×人数×1.2（会社負担）。採用費＝増えた人数×年収×15%。tora_v2.js の team() と run() の人件費・採用費と同じ（計算詳細版 p.17）。
A3: 項目 | B3: 単位 | C3: 1 | D3: 2 | E3: 3 | F3: 4 | G3: 5 | H3: 6 | I3: 7 | J3: 8 | K3: 9 | L3: 10 | M3: 式（言葉）
A4: 年収（万円/年）
A5: 年収：代表（創業者） | B5: 万円/年 | C5: ='前提'!$E$93 -> 480 | D5: ='前提'!$F$93 -> 600 | E5: ='前提'!$G$93 -> 720 | F5: ='前提'!$H$93 -> 720 | G5: ='前提'!$I$93 -> 720 | H5: ='前提'!$J$93 -> 720 | I5: ='前提'!$K$93 -> 720 | J5: ='前提'!$L$93 -> 720 | K5: ='前提'!$M$93 -> 720 | L5: ='前提'!$N$93 -> 720 | M5: 前提6-1
A6: 年収：CTO | B6: 万円/年 | C6: ='前提'!$E$94 -> 1000 | D6: ='前提'!$F$94 -> 1000 | E6: ='前提'!$G$94 -> 1000 | F6: ='前提'!$H$94 -> 1000 | G6: ='前提'!$I$94 -> 1000 | H6: ='前提'!$J$94 -> 1000 | I6: ='前提'!$K$94 -> 1000 | J6: ='前提'!$L$94 -> 1000 | K6: ='前提'!$M$94 -> 1000 | L6: ='前提'!$N$94 -> 1000 | M6: 前提6-2
A7: 年収：エンジニア | B7: 万円/年 | C7: ='前提'!$E$95 -> 800 | D7: ='前提'!$F$95 -> 800 | E7: ='前提'!$G$95 -> 800 | F7: ='前提'!$H$95 -> 800 | G7: ='前提'!$I$95 -> 800 | H7: ='前提'!$J$95 -> 800 | I7: ='前提'!$K$95 -> 800 | J7: ='前提'!$L$95 -> 800 | K7: ='前提'!$M$95 -> 800 | L7: ='前提'!$N$95 -> 800 | M7: 前提6-3
A8: 年収：現場監修（施工管理経験者） | B8: 万円/年 | C8: ='前提'!$E$96 -> 650 | D8: ='前提'!$F$96 -> 650 | E8: ='前提'!$G$96 -> 650 | F8: ='前提'!$H$96 -> 650 | G8: ='前提'!$I$96 -> 650 | H8: ='前提'!$J$96 -> 650 | I8: ='前提'!$K$96 -> 650 | J8: ='前提'!$L$96 -> 650 | K8: ='前提'!$M$96 -> 650 | L8: ='前提'!$N$96 -> 650 | M8: 前提6-4
A9: 年収：導入コンサルタント | B9: 万円/年 | C9: ='前提'!$E$97 -> 600 | D9: ='前提'!$F$97 -> 600 | E9: ='前提'!$G$97 -> 600 | F9: ='前提'!$H$97 -> 600 | G9: ='前提'!$I$97 -> 600 | H9: ='前提'!$J$97 -> 600 | I9: ='前提'!$K$97 -> 600 | J9: ='前提'!$L$97 -> 600 | K9: ='前提'!$M$97 -> 600 | L9: ='前提'!$N$97 -> 600 | M9: 前提6-5
A10: 年収：営業（技術営業） | B10: 万円/年 | C10: ='前提'!$E$98 -> 650 | D10: ='前提'!$F$98 -> 650 | E10: ='前提'!$G$98 -> 650 | F10: ='前提'!$H$98 -> 650 | G10: ='前提'!$I$98 -> 650 | H10: ='前提'!$J$98 -> 650 | I10: ='前提'!$K$98 -> 650 | J10: ='前提'!$L$98 -> 650 | K10: ='前提'!$M$98 -> 650 | L10: ='前提'!$N$98 -> 650 | M10: 前提6-6
A11: 年収：管理（人事・経理・総務） | B11: 万円/年 | C11: ='前提'!$E$99 -> 550 | D11: ='前提'!$F$99 -> 550 | E11: ='前提'!$G$99 -> 550 | F11: ='前提'!$H$99 -> 550 | G11: ='前提'!$I$99 -> 550 | H11: ='前提'!$J$99 -> 550 | I11: ='前提'!$K$99 -> 550 | J11: ='前提'!$L$99 -> 550 | K11: ='前提'!$M$99 -> 550 | L11: ='前提'!$N$99 -> 550 | M11: 前提6-7
A12: 年収：戦略企画 | B12: 万円/年 | C12: ='前提'!$E$100 -> 700 | D12: ='前提'!$F$100 -> 700 | E12: ='前提'!$G$100 -> 700 | F12: ='前提'!$H$100 -> 700 | G12: ='前提'!$I$100 -> 700 | H12: ='前提'!$J$100 -> 700 | I12: ='前提'!$K$100 -> 700 | J12: ='前提'!$L$100 -> 700 | K12: ='前提'!$M$100 -> 700 | L12: ='前提'!$N$100 -> 700 | M12: 前提6-8
A13: 人数（期末）
A14: 人数：代表（創業者） | B14: 人 | C14: ='前提'!$E$101 -> 1 | D14: ='前提'!$F$101 -> 1 | E14: ='前提'!$G$101 -> 1 | F14: ='前提'!$H$101 -> 1 | G14: ='前提'!$I$101 -> 1 | H14: ='前提'!$J$101 -> 1 | I14: ='前提'!$K$101 -> 1 | J14: ='前提'!$L$101 -> 1 | K14: ='前提'!$M$101 -> 1 | L14: ='前提'!$N$101 -> 1 | M14: 前提6-9
A15: 人数：CTO | B15: 人 | C15: ='前提'!$E$102 -> 1 | D15: ='前提'!$F$102 -> 1 | E15: ='前提'!$G$102 -> 1 | F15: ='前提'!$H$102 -> 1 | G15: ='前提'!$I$102 -> 1 | H15: ='前提'!$J$102 -> 1 | I15: ='前提'!$K$102 -> 1 | J15: ='前提'!$L$102 -> 1 | K15: ='前提'!$M$102 -> 1 | L15: ='前提'!$N$102 -> 1 | M15: 前提6-10
A16: 人数：エンジニア | B16: 人 | C16: ='前提'!$E$103 -> 1 | D16: ='前提'!$F$103 -> 2 | E16: ='前提'!$G$103 -> 3 | F16: ='前提'!$H$103 -> 4 | G16: ='前提'!$I$103 -> 5 | H16: ='前提'!$J$103 -> 6 | I16: ='前提'!$K$103 -> 6 | J16: ='前提'!$L$103 -> 7 | K16: ='前提'!$M$103 -> 7 | L16: ='前提'!$N$103 -> 8 | M16: 前提6-11
A17: 人数：現場監修（施工管理経験者） | B17: 人 | C17: ='前提'!$E$104 -> 1 | D17: ='前提'!$F$104 -> 1 | E17: ='前提'!$G$104 -> 1 | F17: ='前提'!$H$104 -> 1 | G17: ='前提'!$I$104 -> 2 | H17: ='前提'!$J$104 -> 2 | I17: ='前提'!$K$104 -> 3 | J17: ='前提'!$L$104 -> 3 | K17: ='前提'!$M$104 -> 3 | L17: ='前提'!$N$104 -> 4 | M17: 前提6-12
A18: 人数：導入コンサルタント | B18: 人 | C18: ='前提'!$E$105 -> 1 | D18: ='前提'!$F$105 -> 2 | E18: ='前提'!$G$105 -> 4 | F18: ='前提'!$H$105 -> 6 | G18: ='前提'!$I$105 -> 8 | H18: ='前提'!$J$105 -> 8 | I18: ='前提'!$K$105 -> 9 | J18: ='前提'!$L$105 -> 9 | K18: ='前提'!$M$105 -> 9 | L18: ='前提'!$N$105 -> 9 | M18: 前提6-13
A19: 人数：営業（技術営業） | B19: 人 | C19: ='前提'!$E$106 -> 0 | D19: ='前提'!$F$106 -> 1 | E19: ='前提'!$G$106 -> 1 | F19: ='前提'!$H$106 -> 3 | G19: ='前提'!$I$106 -> 3 | H19: ='前提'!$J$106 -> 3 | I19: ='前提'!$K$106 -> 4 | J19: ='前提'!$L$106 -> 4 | K19: ='前提'!$M$106 -> 4 | L19: ='前提'!$N$106 -> 4 | M19: 前提6-14
A20: 人数：管理（人事・経理・総務） | B20: 人 | C20: ='前提'!$E$107 -> 0 | D20: ='前提'!$F$107 -> 0 | E20: ='前提'!$G$107 -> 1 | F20: ='前提'!$H$107 -> 1 | G20: ='前提'!$I$107 -> 2 | H20: ='前提'!$J$107 -> 2 | I20: ='前提'!$K$107 -> 2 | J20: ='前提'!$L$107 -> 3 | K20: ='前提'!$M$107 -> 3 | L20: ='前提'!$N$107 -> 3 | M20: 前提6-15
A21: 人数：戦略企画 | B21: 人 | C21: ='前提'!$E$108 -> 0 | D21: ='前提'!$F$108 -> 0 | E21: ='前提'!$G$108 -> 0 | F21: ='前提'!$H$108 -> 1 | G21: ='前提'!$I$108 -> 1 | H21: ='前提'!$J$108 -> 1 | I21: ='前提'!$K$108 -> 1 | J21: ='前提'!$L$108 -> 1 | K21: ='前提'!$M$108 -> 2 | L21: ='前提'!$N$108 -> 2 | M21: 前提6-16
A22: 計画の社員数 | B22: 人 | C22: =SUM(C14:C21) -> 5 | D22: =SUM(D14:D21) -> 8 | E22: =SUM(E14:E21) -> 12 | F22: =SUM(F14:F21) -> 18 | G22: =SUM(G14:G21) -> 23 | H22: =SUM(H14:H21) -> 24 | I22: =SUM(I14:I21) -> 27 | J22: =SUM(J14:J21) -> 29 | ... L22: =SUM(L14:L21) -> 32 | M22: 8つの役割の合計
A23: 人件費（年収×人数×会社負担）
A24: 人件費：代表（創業者） | B24: 万円/年 | C24: =$C$5*$C$14*'前提'!$E$109 -> 576 | D24: =$D$5*$D$14*'前提'!$E$109 -> 720 | E24: =$E$5*$E$14*'前提'!$E$109 -> 864 | F24: =$F$5*$F$14*'前提'!$E$109 -> 864 | G24: =$G$5*$G$14*'前提'!$E$109 -> 864 | H24: =$H$5*$H$14*'前提'!$E$109 -> 864 | I24: =$I$5*$I$14*'前提'!$E$109 -> 864 | J24: =$J$5*$J$14*'前提'!$E$109 -> 864 | K24: =$K$5*$K$14*'前提'!$E$109 -> 864 | L24: =$L$5*$L$14*'前提'!$E$109 -> 864 | M24: 年収×人数×1.2
A25: 人件費：CTO | B25: 万円/年 | C25: =$C$6*$C$15*'前提'!$E$109 -> 1200 | D25: =$D$6*$D$15*'前提'!$E$109 -> 1200 | E25: =$E$6*$E$15*'前提'!$E$109 -> 1200 | F25: =$F$6*$F$15*'前提'!$E$109 -> 1200 | G25: =$G$6*$G$15*'前提'!$E$109 -> 1200 | H25: =$H$6*$H$15*'前提'!$E$109 -> 1200 | I25: =$I$6*$I$15*'前提'!$E$109 -> 1200 | J25: =$J$6*$J$15*'前提'!$E$109 -> 1200 | K25: =$K$6*$K$15*'前提'!$E$109 -> 1200 | L25: =$L$6*$L$15*'前提'!$E$109 -> 1200 | M25: 年収×人数×1.2
A26: 人件費：エンジニア | B26: 万円/年 | C26: =$C$7*$C$16*'前提'!$E$109 -> 960 | D26: =$D$7*$D$16*'前提'!$E$109 -> 1920 | E26: =$E$7*$E$16*'前提'!$E$109 -> 2880 | F26: =$F$7*$F$16*'前提'!$E$109 -> 3840 | G26: =$G$7*$G$16*'前提'!$E$109 -> 4800 | H26: =$H$7*$H$16*'前提'!$E$109 -> 5760 | I26: =$I$7*$I$16*'前提'!$E$109 -> 5760 | J26: =$J$7*$J$16*'前提'!$E$109 -> 6720 | K26: =$K$7*$K$16*'前提'!$E$109 -> 6720 | L26: =$L$7*$L$16*'前提'!$E$109 -> 7680 | M26: 年収×人数×1.2
A27: 人件費：現場監修（施工管理経験者） | B27: 万円/年 | C27: =$C$8*$C$17*'前提'!$E$109 -> 780 | D27: =$D$8*$D$17*'前提'!$E$109 -> 780 | E27: =$E$8*$E$17*'前提'!$E$109 -> 780 | F27: =$F$8*$F$17*'前提'!$E$109 -> 780 | G27: =$G$8*$G$17*'前提'!$E$109 -> 1560 | H27: =$H$8*$H$17*'前提'!$E$109 -> 1560 | I27: =$I$8*$I$17*'前提'!$E$109 -> 2340 | J27: =$J$8*$J$17*'前提'!$E$109 -> 2340 | K27: =$K$8*$K$17*'前提'!$E$109 -> 2340 | L27: =$L$8*$L$17*'前提'!$E$109 -> 3120 | M27: 年収×人数×1.2
A28: 人件費：導入コンサルタント | B28: 万円/年 | C28: =$C$9*$C$18*'前提'!$E$109 -> 720 | D28: =$D$9*$D$18*'前提'!$E$109 -> 1440 | E28: =$E$9*$E$18*'前提'!$E$109 -> 2880 | F28: =$F$9*$F$18*'前提'!$E$109 -> 4320 | G28: =$G$9*$G$18*'前提'!$E$109 -> 5760 | H28: =$H$9*$H$18*'前提'!$E$109 -> 5760 | I28: =$I$9*$I$18*'前提'!$E$109 -> 6480 | J28: =$J$9*$J$18*'前提'!$E$109 -> 6480 | K28: =$K$9*$K$18*'前提'!$E$109 -> 6480 | L28: =$L$9*$L$18*'前提'!$E$109 -> 6480 | M28: 年収×人数×1.2
A29: 人件費：営業（技術営業） | B29: 万円/年 | C29: =$C$10*$C$19*'前提'!$E$109 -> 0 | D29: =$D$10*$D$19*'前提'!$E$109 -> 780 | E29: =$E$10*$E$19*'前提'!$E$109 -> 780 | F29: =$F$10*$F$19*'前提'!$E$109 -> 2340 | G29: =$G$10*$G$19*'前提'!$E$109 -> 2340 | H29: =$H$10*$H$19*'前提'!$E$109 -> 2340 | I29: =$I$10*$I$19*'前提'!$E$109 -> 3120 | J29: =$J$10*$J$19*'前提'!$E$109 -> 3120 | K29: =$K$10*$K$19*'前提'!$E$109 -> 3120 | L29: =$L$10*$L$19*'前提'!$E$109 -> 3120 | M29: 年収×人数×1.2
A30: 人件費：管理（人事・経理・総務） | B30: 万円/年 | C30: =$C$11*$C$20*'前提'!$E$109 -> 0 | D30: =$D$11*$D$20*'前提'!$E$109 -> 0 | E30: =$E$11*$E$20*'前提'!$E$109 -> 660 | F30: =$F$11*$F$20*'前提'!$E$109 -> 660 | G30: =$G$11*$G$20*'前提'!$E$109 -> 1320 | H30: =$H$11*$H$20*'前提'!$E$109 -> 1320 | I30: =$I$11*$I$20*'前提'!$E$109 -> 1320 | J30: =$J$11*$J$20*'前提'!$E$109 -> 1980 | K30: =$K$11*$K$20*'前提'!$E$109 -> 1980 | L30: =$L$11*$L$20*'前提'!$E$109 -> 1980 | M30: 年収×人数×1.2
A31: 人件費：戦略企画 | B31: 万円/年 | C31: =$C$12*$C$21*'前提'!$E$109 -> 0 | D31: =$D$12*$D$21*'前提'!$E$109 -> 0 | E31: =$E$12*$E$21*'前提'!$E$109 -> 0 | F31: =$F$12*$F$21*'前提'!$E$109 -> 840 | G31: =$G$12*$G$21*'前提'!$E$109 -> 840 | H31: =$H$12*$H$21*'前提'!$E$109 -> 840 | I31: =$I$12*$I$21*'前提'!$E$109 -> 840 | J31: =$J$12*$J$21*'前提'!$E$109 -> 840 | K31: =$K$12*$K$21*'前提'!$E$109 -> 1680 | L31: =$L$12*$L$21*'前提'!$E$109 -> 1680 | M31: 年収×人数×1.2
A32: 人件費の合計（計画） | B32: 万円/年 | C32: =SUM(C24:C31) -> 4236 | D32: =SUM(D24:D31) -> 6840 | E32: =SUM(E24:E31) -> 10044 | F32: =SUM(F24:F31) -> 14844 | G32: =SUM(G24:G31) -> 18684 | H32: =SUM(H24:H31) -> 19644 | I32: =SUM(I24:I31) -> 21924 | J32: =SUM(J24:J31) -> 23544 | ... L32: =SUM(L24:L31) -> 26124 | M32: 8つの役割の合計
A33: 採用費（増えた人の年収×採用費率）
A34: 増員：代表（創業者） | B34: 人 | C34: =$C$14 -> 1 | D34: =MAX(0,$D$14-$C$14) -> 0 | E34: =MAX(0,$E$14-$D$14) -> 0 | F34: =MAX(0,$F$14-$E$14) -> 0 | G34: =MAX(0,$G$14-$F$14) -> 0 | H34: =MAX(0,$H$14-$G$14) -> 0 | I34: =MAX(0,$I$14-$H$14) -> 0 | J34: =MAX(0,$J$14-$I$14) -> 0 | K34: =MAX(0,$K$14-$J$14) -> 0 | L34: =MAX(0,$L$14-$K$14) -> 0 | M34: その年の人数−前の年の人数（減ったときは0）。1年目は開業時0人から
A35: 増員：CTO | B35: 人 | C35: =$C$15 -> 1 | D35: =MAX(0,$D$15-$C$15) -> 0 | E35: =MAX(0,$E$15-$D$15) -> 0 | F35: =MAX(0,$F$15-$E$15) -> 0 | G35: =MAX(0,$G$15-$F$15) -> 0 | H35: =MAX(0,$H$15-$G$15) -> 0 | I35: =MAX(0,$I$15-$H$15) -> 0 | J35: =MAX(0,$J$15-$I$15) -> 0 | K35: =MAX(0,$K$15-$J$15) -> 0 | L35: =MAX(0,$L$15-$K$15) -> 0 | M35: その年の人数−前の年の人数（減ったときは0）。1年目は開業時0人から
A36: 増員：エンジニア | B36: 人 | C36: =$C$16 -> 1 | D36: =MAX(0,$D$16-$C$16) -> 1 | E36: =MAX(0,$E$16-$D$16) -> 1 | F36: =MAX(0,$F$16-$E$16) -> 1 | G36: =MAX(0,$G$16-$F$16) -> 1 | H36: =MAX(0,$H$16-$G$16) -> 1 | I36: =MAX(0,$I$16-$H$16) -> 0 | J36: =MAX(0,$J$16-$I$16) -> 1 | K36: =MAX(0,$K$16-$J$16) -> 0 | L36: =MAX(0,$L$16-$K$16) -> 1 | M36: その年の人数−前の年の人数（減ったときは0）。1年目は開業時0人から
A37: 増員：現場監修（施工管理経験者） | B37: 人 | C37: =$C$17 -> 1 | D37: =MAX(0,$D$17-$C$17) -> 0 | E37: =MAX(0,$E$17-$D$17) -> 0 | F37: =MAX(0,$F$17-$E$17) -> 0 | G37: =MAX(0,$G$17-$F$17) -> 1 | H37: =MAX(0,$H$17-$G$17) -> 0 | I37: =MAX(0,$I$17-$H$17) -> 1 | J37: =MAX(0,$J$17-$I$17) -> 0 | K37: =MAX(0,$K$17-$J$17) -> 0 | L37: =MAX(0,$L$17-$K$17) -> 1 | M37: その年の人数−前の年の人数（減ったときは0）。1年目は開業時0人から
A38: 増員：導入コンサルタント | B38: 人 | C38: =$C$18 -> 1 | D38: =MAX(0,$D$18-$C$18) -> 1 | E38: =MAX(0,$E$18-$D$18) -> 2 | F38: =MAX(0,$F$18-$E$18) -> 2 | G38: =MAX(0,$G$18-$F$18) -> 2 | H38: =MAX(0,$H$18-$G$18) -> 0 | I38: =MAX(0,$I$18-$H$18) -> 1 | J38: =MAX(0,$J$18-$I$18) -> 0 | K38: =MAX(0,$K$18-$J$18) -> 0 | L38: =MAX(0,$L$18-$K$18) -> 0 | M38: その年の人数−前の年の人数（減ったときは0）。1年目は開業時0人から
A39: 増員：営業（技術営業） | B39: 人 | C39: =$C$19 -> 0 | D39: =MAX(0,$D$19-$C$19) -> 1 | E39: =MAX(0,$E$19-$D$19) -> 0 | F39: =MAX(0,$F$19-$E$19) -> 2 | G39: =MAX(0,$G$19-$F$19) -> 0 | H39: =MAX(0,$H$19-$G$19) -> 0 | I39: =MAX(0,$I$19-$H$19) -> 1 | J39: =MAX(0,$J$19-$I$19) -> 0 | K39: =MAX(0,$K$19-$J$19) -> 0 | L39: =MAX(0,$L$19-$K$19) -> 0 | M39: その年の人数−前の年の人数（減ったときは0）。1年目は開業時0人から
A40: 増員：管理（人事・経理・総務） | B40: 人 | C40: =$C$20 -> 0 | D40: =MAX(0,$D$20-$C$20) -> 0 | E40: =MAX(0,$E$20-$D$20) -> 1 | F40: =MAX(0,$F$20-$E$20) -> 0 | G40: =MAX(0,$G$20-$F$20) -> 1 | H40: =MAX(0,$H$20-$G$20) -> 0 | I40: =MAX(0,$I$20-$H$20) -> 0 | J40: =MAX(0,$J$20-$I$20) -> 1 | K40: =MAX(0,$K$20-$J$20) -> 0 | L40: =MAX(0,$L$20-$K$20) -> 0 | M40: その年の人数−前の年の人数（減ったときは0）。1年目は開業時0人から
...

Sheet 拠点と売上
A1: 拠点と売上：期首−解約＋新規＝期末。売上の柱は既存の利用料
A2: 1年目は試験導入で利用料なし。新規は初年度に半年分。解約は期首×10%を四捨五入（1年目は0）。tora_v2.js の run({years:10}) と同じ式（計算詳細版 p.14・15）。
A3: 項目 | B3: 単位 | C3: 1 | D3: 2 | E3: 3 | F3: 4 | G3: 5 | H3: 6 | I3: 7 | J3: 8 | K3: 9 | L3: 10 | M3: 式（言葉）
A4: 拠点の積み上げ
A5: 期首の拠点 | B5: 拠点 | C5: ='前提'!$E$135 -> 0 | D5: =$C$9 -> 3 | E5: =$D$9 -> 12 | F5: =$E$9 -> 29 | G5: =$F$9 -> 53 | H5: =$G$9 -> 81 | I5: =$H$9 -> 109 | J5: =$I$9 -> 136 | K5: =$J$9 -> 162 | L5: =$K$9 -> 186 | M5: 前の年の期末。1年目は開業時の拠点（前提7-18）
A6: 使う解約率 | B6: 割合/年 | C6: =IF(ISBLANK('前提'!$E$140),'前提'!$E$119,'前提'!$E$140) -> 0.1 | D6: =IF(ISBLANK('前提'!$E$140),'前提'!$E$119,'前提'!$E$140) -> 0.1 | E6: =IF(ISBLANK('前提'!$E$140),'前提'!$E$119,'前提'!$E$140) -> 0.1 | F6: =IF(ISBLANK('前提'!$E$140),'前提'!$E$119,'前提'!$E$140) -> 0.1 | G6: =IF(ISBLANK('前提'!$E$140),'前提'!$E$119,'前提'!$E$140) -> 0.1 | H6: =IF(ISBLANK('前提'!$E$140),'前提'!$E$119,'前提'!$E$140) -> 0.1 | I6: =IF(ISBLANK('前提'!$E$140),'前提'!$E$119,'前提'!$E$140) -> 0.1 | J6: =IF(ISBLANK('前提'!$E$140),'前提'!$E$119,'前提'!$E$140) -> 0.1 | ... L6: =IF(ISBLANK('前提'!$E$140),'前提'!$E$119,'前提'!$E$140) -> 0.1 | M6: 前提8-2が空なら前提7-2
A7: 解約 | B7: 拠点 | C7: =IF(C$3=1,0,ROUND($C$5*$C$6,0)) -> 0 | D7: =IF(D$3=1,0,ROUND($D$5*$D$6,0)) -> 0 | E7: =IF(E$3=1,0,ROUND($E$5*$E$6,0)) -> 1 | F7: =IF(F$3=1,0,ROUND($F$5*$F$6,0)) -> 3 | G7: =IF(G$3=1,0,ROUND($G$5*$G$6,0)) -> 5 | H7: =IF(H$3=1,0,ROUND($H$5*$H$6,0)) -> 8 | I7: =IF(I$3=1,0,ROUND($I$5*$I$6,0)) -> 11 | J7: =IF(J$3=1,0,ROUND($J$5*$J$6,0)) -> 14 | K7: =IF(K$3=1,0,ROUND($K$5*$K$6,0)) -> 16 | L7: =IF(L$3=1,0,ROUND($L$5*$L$6,0)) -> 19 | M7: 1年目は0。2年目から 期首×解約率 を四捨五入
A8: 新規 | B8: 拠点 | C8: ='前提'!$E$118 -> 3 | D8: ='前提'!$F$118 -> 9 | E8: ='前提'!$G$118 -> 18 | F8: ='前提'!$H$118 -> 27 | G8: ='前提'!$I$118 -> 33 | H8: ='前提'!$J$118 -> 36 | I8: ='前提'!$K$118 -> 38 | J8: ='前提'!$L$118 -> 40 | K8: ='前提'!$M$118 -> 40 | L8: ='前提'!$N$118 -> 40 | M8: 前提7-1
A9: 期末の拠点 | B9: 拠点 | C9: =$C$5-$C$7+$C$8 -> 3 | D9: =$D$5-$D$7+$D$8 -> 12 | E9: =$E$5-$E$7+$E$8 -> 29 | F9: =$F$5-$F$7+$F$8 -> 53 | G9: =$G$5-$G$7+$G$8 -> 81 | H9: =$H$5-$H$7+$H$8 -> 109 | I9: =$I$5-$I$7+$I$8 -> 136 | J9: =$J$5-$J$7+$J$8 -> 162 | K9: =$K$5-$K$7+$K$8 -> 186 | L9: =$L$5-$L$7+$L$8 -> 207 | M9: 期首−解約＋新規
A10: 利用料
A11: 通年で課金する拠点（期首−解約） | B11: 拠点 | C11: =$C$5-$C$7 -> 0 | D11: =$D$5-$D$7 -> 3 | E11: =$E$5-$E$7 -> 11 | F11: =$F$5-$F$7 -> 26 | G11: =$G$5-$G$7 -> 48 | H11: =$H$5-$H$7 -> 73 | I11: =$I$5-$I$7 -> 98 | J11: =$J$5-$J$7 -> 122 | K11: =$K$5-$K$7 -> 146 | L11: =$L$5-$L$7 -> 167 | M11: 期首−解約
A12: 1拠点の利用料 | B12: 万円/年 | C12: ='値段と原価'!$C$8 -> 300 | D12: ='値段と原価'!$C$8 -> 300 | E12: ='値段と原価'!$C$8 -> 300 | F12: ='値段と原価'!$C$8 -> 300 | G12: ='値段と原価'!$C$8 -> 300 | H12: ='値段と原価'!$C$8 -> 300 | I12: ='値段と原価'!$C$8 -> 300 | J12: ='値段と原価'!$C$8 -> 300 | ... L12: ='値段と原価'!$C$8 -> 300 | M12: 値段と原価（値段の倍率を反映）
A13: 新規の初年度の課金割合 | B13: 割合 | C13: =IF(C$3='前提'!$E$121,0,'前提'!$E$120) -> 0 | D13: =IF(D$3='前提'!$E$121,0,'前提'!$E$120) -> 0.5 | E13: =IF(E$3='前提'!$E$121,0,'前提'!$E$120) -> 0.5 | F13: =IF(F$3='前提'!$E$121,0,'前提'!$E$120) -> 0.5 | G13: =IF(G$3='前提'!$E$121,0,'前提'!$E$120) -> 0.5 | H13: =IF(H$3='前提'!$E$121,0,'前提'!$E$120) -> 0.5 | I13: =IF(I$3='前提'!$E$121,0,'前提'!$E$120) -> 0.5 | J13: =IF(J$3='前提'!$E$121,0,'前提'!$E$120) -> 0.5 | ... L13: =IF(L$3='前提'!$E$121,0,'前提'!$E$120) -> 0.5 | M13: 試験導入の年（1年目）は0、それ以外は半年分
A14: 既存の利用料 | B14: 万円/年 | C14: =$C$11*$C$12 -> 0 | D14: =$D$11*$D$12 -> 900 | E14: =$E$11*$E$12 -> 3300 | F14: =$F$11*$F$12 -> 7800 | G14: =$G$11*$G$12 -> 14400 | H14: =$H$11*$H$12 -> 21900 | I14: =$I$11*$I$12 -> 29400 | J14: =$J$11*$J$12 -> 36600 | K14: =$K$11*$K$12 -> 43800 | L14: =$L$11*$L$12 -> 50100 | M14: (期首−解約)×1拠点の利用料
A15: 新規の利用料 | B15: 万円/年 | C15: =$C$8*$C$12*$C$13 -> 0 | D15: =$D$8*$D$12*$D$13 -> 1350 | E15: =$E$8*$E$12*$E$13 -> 2700 | F15: =$F$8*$F$12*$F$13 -> 4050 | G15: =$G$8*$G$12*$G$13 -> 4950 | H15: =$H$8*$H$12*$H$13 -> 5400 | I15: =$I$8*$I$12*$I$13 -> 5700 | J15: =$J$8*$J$12*$J$13 -> 6000 | K15: =$K$8*$K$12*$K$13 -> 6000 | L15: =$L$8*$L$12*$L$13 -> 6000 | M15: 新規×1拠点の利用料×初年度の課金割合
A16: 利用料の合計 | B16: 万円/年 | C16: =$C$14+$C$15 -> 0 | D16: =$D$14+$D$15 -> 2250 | E16: =$E$14+$E$15 -> 6000 | F16: =$F$14+$F$15 -> 11850 | G16: =$G$14+$G$15 -> 19350 | H16: =$H$14+$H$15 -> 27300 | I16: =$I$14+$I$15 -> 35100 | J16: =$J$14+$J$15 -> 42600 | K16: =$K$14+$K$15 -> 49800 | L16: =$L$14+$L$15 -> 56100 | M16: 既存＋新規
A17: 参考：解約で減った利用料 | B17: 万円/年 | C17: =$C$7*$C$12 -> 0 | D17: =$D$7*$D$12 -> 0 | E17: =$E$7*$E$12 -> 300 | F17: =$F$7*$F$12 -> 900 | G17: =$G$7*$G$12 -> 1500 | H17: =$H$7*$H$12 -> 2400 | I17: =$I$7*$I$12 -> 3300 | J17: =$J$7*$J$12 -> 4200 | K17: =$K$7*$K$12 -> 4800 | L17: =$L$7*$L$12 -> 5700 | M17: 解約×1拠点の利用料
A18: サービスと売上
A19: 導入支援 | B19: 万円/年 | C19: =$C$8*'前提'!$E$25 -> 600 | D19: =$D$8*'前提'!$E$25 -> 1800 | E19: =$E$8*'前提'!$E$25 -> 3600 | F19: =$F$8*'前提'!$E$25 -> 5400 | G19: =$G$8*'前提'!$E$25 -> 6600 | H19: =$H$8*'前提'!$E$25 -> 7200 | I19: =$I$8*'前提'!$E$25 -> 7600 | J19: =$J$8*'前提'!$E$25 -> 8000 | K19: =$K$8*'前提'!$E$25 -> 8000 | L19: =$L$8*'前提'!$E$25 -> 8000 | M19: 新規×200万円
A20: 個社設定 | B20: 万円/年 | C20: ='前提'!$E$124 -> 600 | D20: ='前提'!$F$124 -> 750 | E20: ='前提'!$G$124 -> 1100 | F20: ='前提'!$H$124 -> 550 | G20: ='前提'!$I$124 -> 950 | H20: ='前提'!$J$124 -> 1000 | I20: ='前提'!$K$124 -> 1100 | J20: ='前提'!$L$124 -> 1200 | K20: ='前提'!$M$124 -> 1300 | L20: ='前提'!$N$124 -> 1400 | M20: 前提7-7
A21: サービスの売上 | B21: 万円/年 | C21: =$C$19+$C$20 -> 1200 | D21: =$D$19+$D$20 -> 2550 | E21: =$E$19+$E$20 -> 4700 | F21: =$F$19+$F$20 -> 5950 | G21: =$G$19+$G$20 -> 7550 | H21: =$H$19+$H$20 -> 8200 | I21: =$I$19+$I$20 -> 8700 | J21: =$J$19+$J$20 -> 9200 | K21: =$K$19+$K$20 -> 9300 | L21: =$L$19+$L$20 -> 9400 | M21: 導入支援＋個社設定
A22: 売上 | B22: 万円/年 | C22: =$C$16+$C$21 -> 1200 | D22: =$D$16+$D$21 -> 4800 | E22: =$E$16+$E$21 -> 10700 | F22: =$F$16+$F$21 -> 17800 | G22: =$G$16+$G$21 -> 26900 | H22: =$H$16+$H$21 -> 35500 | I22: =$I$16+$I$21 -> 43800 | J22: =$J$16+$J$21 -> 51800 | K22: =$K$16+$K$21 -> 59100 | L22: =$L$16+$L$21 -> 65500 | M22: 利用料＋サービス
A23: 既存の利用料の割合 | B23: 割合 | C23: =$C$14/$C$22 -> 0 | D23: =$D$14/$D$22 -> 0.1875 | E23: =$E$14/$E$22 -> 0.30841121 | F23: =$F$14/$F$22 -> 0.43820225 | G23: =$G$14/$G$22 -> 0.53531599 | H23: =$H$14/$H$22 -> 0.61690141 | I23: =$I$14/$I$22 -> 0.67123288 | J23: =$J$14/$J$22 -> 0.70656371 | K23: =$K$14/$K$22 -> 0.74111675 | L23: =$L$14/$L$22 -> 0.7648855 | M23: 既存の利用料÷売上

Sheet 損益と現金
A1: 損益と現金：10台のままでも6年目に黒字、8年目に累計を取り戻す
A2: 販管費＝人件費−原価への振替＋採用費＋その他の経費＋顧問。導入支援と個社設定の人件費は原価へ振り替える。tora_v2.js の run({years:10}) と同じ式（計算詳細版 p.3・18・30）。
A3: 項目 | B3: 単位 | C3: 1 | D3: 2 | E3: 3 | F3: 4 | G3: 5 | H3: 6 | I3: 7 | J3: 8 | K3: 9 | L3: 10 | M3: 式（言葉）
A4: 原価
A5: 課金する拠点（通年換算） | B5: 拠点 | C5: ='拠点と売上'!$C$11+'拠点と売上'!$C$8*'拠点と売上'!$C$13 -> 0 | D5: ='拠点と売上'!$D$11+'拠点と売上'!$D$8*'拠点と売上'!$D$13 -> 7.5 | E5: ='拠点と売上'!$E$11+'拠点と売上'!$E$8*'拠点と売上'!$E$13 -> 20 | F5: ='拠点と売上'!$F$11+'拠点と売上'!$F$8*'拠点と売上'!$F$13 -> 39.5 | G5: ='拠点と売上'!$G$11+'拠点と売上'!$G$8*'拠点と売上'!$G$13 -> 64.5 | H5: ='拠点と売上'!$H$11+'拠点と売上'!$H$8*'拠点と売上'!$H$13 -> 91 | I5: ='拠点と売上'!$I$11+'拠点と売上'!$I$8*'拠点と売上'!$I$13 -> 117 | J5: ='拠点と売上'!$J$11+'拠点と売上'!$J$8*'拠点と売上'!$J$13 -> 142 | K5: ='拠点と売上'!$K$11+'拠点と売上'!$K$8*'拠点と売上'!$K$13 -> 166 | L5: ='拠点と売上'!$L$11+'拠点と売上'!$L$8*'拠点と売上'!$L$13 -> 187 | M5: (期首−解約)＋新規×初年度の課金割合
A6: 1拠点の原価 | B6: 万円/年 | C6: ='値段と原価'!$C$14 -> 84 | D6: ='値段と原価'!$C$14 -> 84 | E6: ='値段と原価'!$C$14 -> 84 | F6: ='値段と原価'!$C$14 -> 84 | G6: ='値段と原価'!$C$14 -> 84 | H6: ='値段と原価'!$C$14 -> 84 | I6: ='値段と原価'!$C$14 -> 84 | J6: ='値段と原価'!$C$14 -> 84 | ... L6: ='値段と原価'!$C$14 -> 84 | M6: 値段と原価（データ基盤＋1台の原価×台数）
A7: 試験導入の原価（3か月分） | B7: 万円/年 | C7: =IF(C$3='前提'!$E$121,'拠点と売上'!$C$8*$C$6*'前提'!$E$123,0) -> 63 | D7: =IF(D$3='前提'!$E$121,'拠点と売上'!$D$8*$D$6*'前提'!$E$123,0) -> 0 | E7: =IF(E$3='前提'!$E$121,'拠点と売上'!$E$8*$E$6*'前提'!$E$123,0) -> 0 | F7: =IF(F$3='前提'!$E$121,'拠点と売上'!$F$8*$F$6*'前提'!$E$123,0) -> 0 | G7: =IF(G$3='前提'!$E$121,'拠点と売上'!$G$8*$G$6*'前提'!$E$123,0) -> 0 | H7: =IF(H$3='前提'!$E$121,'拠点と売上'!$H$8*$H$6*'前提'!$E$123,0) -> 0 | I7: =IF(I$3='前提'!$E$121,'拠点と売上'!$I$8*$I$6*'前提'!$E$123,0) -> 0 | J7: =IF(J$3='前提'!$E$121,'拠点と売上'!$J$8*$J$6*'前提'!$E$123,0) -> 0 | K7: =IF(K$3='前提'!$E$121,'拠点と売上'!$K$8*$K$6*'前提'!$E$123,0) -> 0 | L7: =IF(L$3='前提'!$E$121,'拠点と売上'!$L$8*$L$6*'前提'!$E$123,0) -> 0 | M7: 試験導入の年だけ 新規×1拠点の原価×3/12
A8: 利用料の原価 | B8: 万円/年 | C8: =$C$5*$C$6+$C$7 -> 63 | D8: =$D$5*$D$6+$D$7 -> 630 | E8: =$E$5*$E$6+$E$7 -> 1680 | F8: =$F$5*$F$6+$F$7 -> 3318 | G8: =$G$5*$G$6+$G$7 -> 5418 | H8: =$H$5*$H$6+$H$7 -> 7644 | I8: =$I$5*$I$6+$I$7 -> 9828 | J8: =$J$5*$J$6+$J$7 -> 11928 | K8: =$K$5*$K$6+$K$7 -> 13944 | L8: =$L$5*$L$6+$L$7 -> 15708 | M8: 課金する拠点×1拠点の原価＋試験導入の原価
A9: 導入支援の人件費 | B9: 万円/年 | C9: ='拠点と売上'!$C$8*'導入支援'!$C$17 -> 378 | D9: ='拠点と売上'!$D$8*'導入支援'!$C$17 -> 1134 | E9: ='拠点と売上'!$E$8*'導入支援'!$C$17 -> 2268 | F9: ='拠点と売上'!$F$8*'導入支援'!$C$17 -> 3402 | G9: ='拠点と売上'!$G$8*'導入支援'!$C$17 -> 4158 | H9: ='拠点と売上'!$H$8*'導入支援'!$C$17 -> 4536 | I9: ='拠点と売上'!$I$8*'導入支援'!$C$17 -> 4788 | J9: ='拠点と売上'!$J$8*'導入支援'!$C$17 -> 5040 | K9: ='拠点と売上'!$K$8*'導入支援'!$C$17 -> 5040 | L9: ='拠点と売上'!$L$8*'導入支援'!$C$17 -> 5040 | M9: 新規×126万円（42人日×3万円）
A10: 導入支援の交通費 | B10: 万円/年 | C10: ='拠点と売上'!$C$8*'前提'!$E$88 -> 45 | D10: ='拠点と売上'!$D$8*'前提'!$E$88 -> 135 | E10: ='拠点と売上'!$E$8*'前提'!$E$88 -> 270 | F10: ='拠点と売上'!$F$8*'前提'!$E$88 -> 405 | G10: ='拠点と売上'!$G$8*'前提'!$E$88 -> 495 | H10: ='拠点と売上'!$H$8*'前提'!$E$88 -> 540 | I10: ='拠点と売上'!$I$8*'前提'!$E$88 -> 570 | J10: ='拠点と売上'!$J$8*'前提'!$E$88 -> 600 | K10: ='拠点と売上'!$K$8*'前提'!$E$88 -> 600 | L10: ='拠点と売上'!$L$8*'前提'!$E$88 -> 600 | M10: 新規×15万円
A11: 導入支援の原価 | B11: 万円/年 | C11: =$C$9+$C$10 -> 423 | D11: =$D$9+$D$10 -> 1269 | E11: =$E$9+$E$10 -> 2538 | F11: =$F$9+$F$10 -> 3807 | G11: =$G$9+$G$10 -> 4653 | H11: =$H$9+$H$10 -> 5076 | I11: =$I$9+$I$10 -> 5358 | J11: =$J$9+$J$10 -> 5640 | K11: =$K$9+$K$10 -> 5640 | L11: =$L$9+$L$10 -> 5640 | M11: 人件費＋交通費
A12: 個社設定の人件費 | B12: 万円/年 | C12: ='拠点と売上'!$C$20*(1-'前提'!$E$125) -> 400 | D12: ='拠点と売上'!$D$20*(1-'前提'!$E$125) -> 500 | E12: ='拠点と売上'!$E$20*(1-'前提'!$E$125) -> 733.33333 | F12: ='拠点と売上'!$F$20*(1-'前提'!$E$125) -> 366.66667 | G12: ='拠点と売上'!$G$20*(1-'前提'!$E$125) -> 633.33333 | H12: ='拠点と売上'!$H$20*(1-'前提'!$E$125) -> 666.66667 | I12: ='拠点と売上'!$I$20*(1-'前提'!$E$125) -> 733.33333 | J12: ='拠点と売上'!$J$20*(1-'前提'!$E$125) -> 800 | K12: ='拠点と売上'!$K$20*(1-'前提'!$E$125) -> 866.66667 | L12: ='拠点と売上'!$L$20*(1-'前提'!$E$125) -> 933.33333 | M12: 個社設定×2/3（粗利1/3）
A13: 原価の合計 | B13: 万円/年 | C13: =$C$8+$C$11+$C$12 -> 886 | D13: =$D$8+$D$11+$D$12 -> 2399 | E13: =$E$8+$E$11+$E$12 -> 4951.3333 | F13: =$F$8+$F$11+$F$12 -> 7491.6667 | G13: =$G$8+$G$11+$G$12 -> 10704.333 | H13: =$H$8+$H$11+$H$12 -> 13386.667 | I13: =$I$8+$I$11+$I$12 -> 15919.333 | J13: =$J$8+$J$11+$J$12 -> 18368 | K13: =$K$8+$K$11+$K$12 -> 20450.667 | L13: =$L$8+$L$11+$L$12 -> 22281.333 | M13: 利用料の原価＋導入支援の原価＋個社設定の人件費
A14: 粗利
A15: 売上 | B15: 万円/年 | C15: ='拠点と売上'!$C$22 -> 1200 | D15: ='拠点と売上'!$D$22 -> 4800 | E15: ='拠点と売上'!$E$22 -> 10700 | F15: ='拠点と売上'!$F$22 -> 17800 | G15: ='拠点と売上'!$G$22 -> 26900 | H15: ='拠点と売上'!$H$22 -> 35500 | I15: ='拠点と売上'!$I$22 -> 43800 | J15: ='拠点と売上'!$J$22 -> 51800 | K15: ='拠点と売上'!$K$22 -> 59100 | L15: ='拠点と売上'!$L$22 -> 65500 | M15: 拠点と売上
A16: 粗利 | B16: 万円/年 | C16: =$C$15-$C$13 -> 314 | D16: =$D$15-$D$13 -> 2401 | E16: =$E$15-$E$13 -> 5748.6667 | F16: =$F$15-$F$13 -> 10308.333 | G16: =$G$15-$G$13 -> 16195.667 | H16: =$H$15-$H$13 -> 22113.333 | I16: =$I$15-$I$13 -> 27880.667 | J16: =$J$15-$J$13 -> 33432 | K16: =$K$15-$K$13 -> 38649.333 | L16: =$L$15-$L$13 -> 43218.667 | M16: 売上−原価
A17: 粗利率 | B17: 割合 | C17: =$C$16/$C$15 -> 0.26166667 | D17: =$D$16/$D$15 -> 0.50020833 | E17: =$E$16/$E$15 -> 0.53725857 | F17: =$F$16/$F$15 -> 0.57911985 | G17: =$G$16/$G$15 -> 0.60206939 | H17: =$H$16/$H$15 -> 0.6229108 | I17: =$I$16/$I$15 -> 0.6365449 | J17: =$J$16/$J$15 -> 0.64540541 | K17: =$K$16/$K$15 -> 0.65396503 | L17: =$L$16/$L$15 -> 0.65982697 | M17: 粗利÷売上
A18: 利用料の粗利率 | B18: 割合 | C18: =IF('拠点と売上'!$C$16=0,0,1-$C$8/'拠点と売上'!$C$16) -> 0 | D18: =IF('拠点と売上'!$D$16=0,0,1-$D$8/'拠点と売上'!$D$16) -> 0.72 | E18: =IF('拠点と売上'!$E$16=0,0,1-$E$8/'拠点と売上'!$E$16) -> 0.72 | F18: =IF('拠点と売上'!$F$16=0,0,1-$F$8/'拠点と売上'!$F$16) -> 0.72 | G18: =IF('拠点と売上'!$G$16=0,0,1-$G$8/'拠点と売上'!$G$16) -> 0.72 | H18: =IF('拠点と売上'!$H$16=0,0,1-$H$8/'拠点と売上'!$H$16) -> 0.72 | I18: =IF('拠点と売上'!$I$16=0,0,1-$I$8/'拠点と売上'!$I$16) -> 0.72 | J18: =IF('拠点と売上'!$J$16=0,0,1-$J$8/'拠点と売上'!$J$16) -> 0.72 | K18: =IF('拠点と売上'!$K$16=0,0,1-$K$8/'拠点と売上'!$K$16) -> 0.72 | L18: =IF('拠点と売上'!$L$16=0,0,1-$L$8/'拠点と売上'!$L$16) -> 0.72 | M18: 1−利用料の原価÷利用料（1年目は利用料がないので0）
A19: 販管費
A20: 人件費 | B20: 万円/年 | C20: ='体制と人件費'!$C$48 -> 4236 | D20: ='体制と人件費'!$D$48 -> 6840 | E20: ='体制と人件費'!$E$48 -> 10044 | F20: ='体制と人件費'!$F$48 -> 14844 | G20: ='体制と人件費'!$G$48 -> 18684 | H20: ='体制と人件費'!$H$48 -> 19644 | I20: ='体制と人件費'!$I$48 -> 21924 | J20: ='体制と人件費'!$J$48 -> 23544 | K20: ='体制と人件費'!$K$48 -> 24384 | L20: ='体制と人件費'!$L$48 -> 26124 | M20: 体制と人件費
A21: 原価への振替 | B21: 万円/年 | C21: =$C$9+$C$12 -> 778 | D21: =$D$9+$D$12 -> 1634 | E21: =$E$9+$E$12 -> 3001.3333 | F21: =$F$9+$F$12 -> 3768.6667 | G21: =$G$9+$G$12 -> 4791.3333 | H21: =$H$9+$H$12 -> 5202.6667 | I21: =$I$9+$I$12 -> 5521.3333 | J21: =$J$9+$J$12 -> 5840 | K21: =$K$9+$K$12 -> 5906.6667 | L21: =$L$9+$L$12 -> 5973.3333 | M21: 導入支援の人件費＋個社設定の人件費（販管費から引く）
A22: 採用費 | B22: 万円/年 | C22: ='体制と人件費'!$C$49 -> 529.5 | D22: ='体制と人件費'!$D$49 -> 307.5 | E22: ='体制と人件費'!$E$49 -> 382.5 | F22: ='体制と人件費'!$F$49 -> 600 | G22: ='体制と人件費'!$G$49 -> 480 | H22: ='体制と人件費'!$H$49 -> 120 | I22: ='体制と人件費'!$I$49 -> 285 | J22: ='体制と人件費'!$J$49 -> 202.5 | K22: ='体制と人件費'!$K$49 -> 105 | L22: ='体制と人件費'!$L$49 -> 217.5 | M22: 体制と人件費
A23: その他の経費（7項目） | B23: 万円/年 | C23: ='前提'!$E$126+'前提'!$E$127+'前提'!$E$128+'前提'!$E$129+'前提'!$E$130+'前提'!$E$131+'前提'!$E$132 -> 990 | D23: ='前提'!$F$126+'前提'!$F$127+'前提'!$F$128+'前提'!$F$129+'前提'!$F$130+'前提'!$F$131+'前提'!$F$132 -> 1470 | E23: ='前提'!$G$126+'前提'!$G$127+'前提'!$G$128+'前提'!$G$129+'前提'!$G$130+'前提'!$G$131+'前提'!$G$132 -> 1840 | F23: ='前提'!$H$126+'前提'!$H$127+'前提'!$H$128+'前提'!$H$129+'前提'!$H$130+'前提'!$H$131+'前提'!$H$132 -> 2310 | G23: ='前提'!$I$126+'前提'!$I$127+'前提'!$I$128+'前提'!$I$129+'前提'!$I$130+'前提'!$I$131+'前提'!$I$132 -> 2760 | H23: ='前提'!$J$126+'前提'!$J$127+'前提'!$J$128+'前提'!$J$129+'前提'!$J$130+'前提'!$J$131+'前提'!$J$132 -> 2850 | I23: ='前提'!$K$126+'前提'!$K$127+'前提'!$K$128+'前提'!$K$129+'前提'!$K$130+'前提'!$K$131+'前提'!$K$132 -> 3130 | J23: ='前提'!$L$126+'前提'!$L$127+'前提'!$L$128+'前提'!$L$129+'前提'!$L$130+'前提'!$L$131+'前提'!$L$132 -> 3340 | K23: ='前提'!$M$126+'前提'!$M$127+'前提'!$M$128+'前提'!$M$129+'前提'!$M$130+'前提'!$M$131+'前提'!$M$132 -> 3580 | L23: ='前提'!$N$126+'前提'!$N$127+'前提'!$N$128+'前提'!$N$129+'前提'!$N$130+'前提'!$N$131+'前提'!$N$132 -> 3690 | M23: オフィス＋広告＋交通費＋端末・ソフト＋専門家＋雑費＋AIの学習費（前提7-9〜7-15）
A24: 社外顧問 | B24: 万円/年 | C24: ='前提'!$E$115 -> 180 | D24: ='前提'!$E$115 -> 180 | E24: ='前提'!$E$115 -> 180 | F24: ='前提'!$E$115 -> 180 | G24: ='前提'!$E$115 -> 180 | H24: ='前提'!$E$115 -> 180 | I24: ='前提'!$E$115 -> 180 | J24: ='前提'!$E$115 -> 180 | ... L24: ='前提'!$E$115 -> 180 | M24: 月15万円×12
A25: 販管費 | B25: 万円/年 | C25: =$C$20-$C$21+$C$22+$C$23+$C$24 -> 5157.5 | D25: =$D$20-$D$21+$D$22+$D$23+$D$24 -> 7163.5 | E25: =$E$20-$E$21+$E$22+$E$23+$E$24 -> 9445.1667 | F25: =$F$20-$F$21+$F$22+$F$23+$F$24 -> 14165.333 | G25: =$G$20-$G$21+$G$22+$G$23+$G$24 -> 17312.667 | H25: =$H$20-$H$21+$H$22+$H$23+$H$24 -> 17591.333 | I25: =$I$20-$I$21+$I$22+$I$23+$I$24 -> 19997.667 | J25: =$J$20-$J$21+$J$22+$J$23+$J$24 -> 21426.5 | K25: =$K$20-$K$21+$K$22+$K$23+$K$24 -> 22342.333 | L25: =$L$20-$L$21+$L$22+$L$23+$L$24 -> 24238.167 | M25: 人件費−振替＋採用費＋その他＋顧問
A26: 営業利益と現金
A27: 営業利益 | B27: 万円/年 | C27: =$C$16-$C$25 -> -4843.5 | D27: =$D$16-$D$25 -> -4762.5 | E27: =$E$16-$E$25 -> -3696.5 | F27: =$F$16-$F$25 -> -3857 | G27: =$G$16-$G$25 -> -1117 | H27: =$H$16-$H$25 -> 4522 | I27: =$I$16-$I$25 -> 7883 | J27: =$J$16-$J$25 -> 12005.5 | K27: =$K$16-$K$25 -> 16307 | L27: =$L$16-$L$25 -> 18980.5 | M27: 粗利−販管費
A28: 累計の営業損益 | B28: 万円 | C28: =$C$27 -> -4843.5 | D28: =$C$28+$D$27 -> -9606 | E28: =$D$28+$E$27 -> -13302.5 | F28: =$E$28+$F$27 -> -17159.5 | G28: =$F$28+$G$27 -> -18276.5 | H28: =$G$28+$H$27 -> -13754.5 | I28: =$H$28+$I$27 -> -5871.5 | J28: =$I$28+$J$27 -> 6134 | K28: =$J$28+$K$27 -> 22441 | L28: =$K$28+$L$27 -> 41421.5 | M28: 前の年の累計＋その年の営業利益
A29: 資金投入 | B29: 万円/年 | C29: ='前提'!$E$133 -> 20000 | D29: ='前提'!$F$133 -> 0 | E29: ='前提'!$G$133 -> 5000 | F29: ='前提'!$H$133 -> 0 | G29: ='前提'!$I$133 -> 0 | H29: ='前提'!$J$133 -> 0 | I29: ='前提'!$K$133 -> 0 | J29: ='前提'!$L$133 -> 0 | K29: ='前提'!$M$133 -> 0 | L29: ='前提'!$N$133 -> 0 | M29: 前提7-16（準備期の500万円は別）
A30: 期末の現金 | B30: 万円 | C30: ='前提'!$E$136+$C$29+$C$27 -> 15156.5 | D30: =$C$30+$D$29+$D$27 -> 10394 | E30: =$D$30+$E$29+$E$27 -> 11697.5 | F30: =$E$30+$F$29+$F$27 -> 7840.5 | G30: =$F$30+$G$29+$G$27 -> 6723.5 | H30: =$G$30+$H$29+$H$27 -> 11245.5 | I30: =$H$30+$I$29+$I$27 -> 19128.5 | J30: =$I$30+$J$29+$J$27 -> 31134 | K30: =$J$30+$K$29+$K$27 -> 47441 | L30: =$K$30+$L$29+$L$27 -> 66421.5 | M30: 前の年の現金＋資金投入＋営業利益。1年目は期首0から
A31: （営業利益が黒字の年） | B31: 年目 | C31: =IF($C$27>0,C$3,"") | D31: =IF($D$27>0,D$3,"") | E31: =IF($E$27>0,E$3,"") | F31: =IF($F$27>0,F$3,"") | G31: =IF($G$27>0,G$3,"") | H31: =IF($H$27>0,H$3,"") -> 6 | I31: =IF($I$27>0,I$3,"") -> 7 | J31: =IF($J$27>0,J$3,"") -> 8 | K31: =IF($K$27>0,K$3,"") -> 9 | L31: =IF($L$27>0,L$3,"") -> 10 | M31: 黒字なら年の番号、赤字なら空
A32: （累計が黒字の年） | B32: 年目 | C32: =IF($C$28>0,C$3,"") | D32: =IF($D$28>0,D$3,"") | E32: =IF($E$28>0,E$3,"") | F32: =IF($F$28>0,F$3,"") | G32: =IF($G$28>0,G$3,"") | H32: =IF($H$28>0,H$3,"") | I32: =IF($I$28>0,I$3,"") | J32: =IF($J$28>0,J$3,"") -> 8 | K32: =IF($K$28>0,K$3,"") -> 9 | L32: =IF($L$28>0,L$3,"") -> 10 | M32: 累計が黒字なら年の番号
A33: 結果
A34: 黒字化の年（10年で） | B34: 年目 | C34: =IF(COUNT($C$31:$L$31)=0,"10年でなし",MIN($C$31:$L$31)) -> 6 | D34: 営業利益が初めて黒字になる年
A35: 黒字化の年（5年で） | B35: 年目 | C35: =IF(COUNT($C$31:$G$31)=0,"5年でなし",MIN($C$31:$G$31)) -> 5年でなし | D35: 1〜5年目だけで見た場合
A36: 累計回収の年（10年で） | B36: 年目 | C36: =IF(COUNT($C$32:$L$32)=0,"10年でなし",MIN($C$32:$L$32)) -> 8 | D36: 累計の営業損益が初めて黒字になる年
A37: 最低の現金（10年） | B37: 万円 | C37: =MIN($C$30:$L$30) -> 6723.5 | D37: 期末の現金のいちばん低い値
A38: 最低の現金の年 | B38: 年目 | C38: =INDEX($C$3:$L$3,1,MATCH($C$37,$C$30:$L$30,0)) -> 5
A39: 最低の現金（5年） | B39: 万円 | C39: =MIN($C$30:$G$30) -> 6723.5 | D39: 1〜5年目
A40: 累計赤字の底 | B40: 万円 | C40: =MIN($C$28:$L$28) -> -18276.5 | D40: 累計の営業損益のいちばん低い値
...

Sheet 黒字ライン
A1: 黒字ライン：その年の体制で何拠点・何台あれば黒字か
A2: 損益分岐点売上＝販管費÷粗利率。必要な拠点＝(販管費−サービスの粗利)÷1拠点の利用料の粗利216万円（拠点は通年で課金するとして）（計算詳細版 p.19・22）。
A3: 項目 | B3: 単位 | C3: 1 | D3: 2 | E3: 3 | F3: 4 | G3: 5 | H3: 6 | I3: 7 | J3: 8 | K3: 9 | L3: 10 | M3: 式（言葉）
A4: 売上で見る（損益分岐点売上＝販管費÷粗利率）
A5: 販管費 | B5: 万円/年 | C5: ='損益と現金'!$C$25 -> 5157.5 | D5: ='損益と現金'!$D$25 -> 7163.5 | E5: ='損益と現金'!$E$25 -> 9445.1667 | F5: ='損益と現金'!$F$25 -> 14165.333 | G5: ='損益と現金'!$G$25 -> 17312.667 | H5: ='損益と現金'!$H$25 -> 17591.333 | I5: ='損益と現金'!$I$25 -> 19997.667 | J5: ='損益と現金'!$J$25 -> 21426.5 | K5: ='損益と現金'!$K$25 -> 22342.333 | L5: ='損益と現金'!$L$25 -> 24238.167 | M5: 損益と現金
A6: 粗利率 | B6: 割合 | C6: ='損益と現金'!$C$17 -> 0.26166667 | D6: ='損益と現金'!$D$17 -> 0.50020833 | E6: ='損益と現金'!$E$17 -> 0.53725857 | F6: ='損益と現金'!$F$17 -> 0.57911985 | G6: ='損益と現金'!$G$17 -> 0.60206939 | H6: ='損益と現金'!$H$17 -> 0.6229108 | I6: ='損益と現金'!$I$17 -> 0.6365449 | J6: ='損益と現金'!$J$17 -> 0.64540541 | K6: ='損益と現金'!$K$17 -> 0.65396503 | L6: ='損益と現金'!$L$17 -> 0.65982697 | M6: 損益と現金
A7: 損益分岐点売上 | B7: 万円/年 | C7: =$C$5/$C$6 -> 19710.191 | D7: =$D$5/$D$6 -> 14321.033 | E7: =$E$5/$E$6 -> 17580.3 | F7: =$F$5/$F$6 -> 24460.107 | G7: =$G$5/$G$6 -> 28755.268 | H7: =$H$5/$H$6 -> 28240.534 | I7: =$I$5/$I$6 -> 31415.956 | J7: =$J$5/$J$6 -> 33198.513 | K7: =$K$5/$K$6 -> 34164.416 | L7: =$L$5/$L$6 -> 36734.125 | M7: 販管費÷粗利率
A8: 実際の売上 | B8: 万円/年 | C8: ='拠点と売上'!$C$22 -> 1200 | D8: ='拠点と売上'!$D$22 -> 4800 | E8: ='拠点と売上'!$E$22 -> 10700 | F8: ='拠点と売上'!$F$22 -> 17800 | G8: ='拠点と売上'!$G$22 -> 26900 | H8: ='拠点と売上'!$H$22 -> 35500 | I8: ='拠点と売上'!$I$22 -> 43800 | J8: ='拠点と売上'!$J$22 -> 51800 | K8: ='拠点と売上'!$K$22 -> 59100 | L8: ='拠点と売上'!$L$22 -> 65500 | M8: 拠点と売上
A9: 分岐点に対する売上の割合 | B9: 割合 | C9: =$C$8/$C$7 -> 0.06088221 | D9: =$D$8/$D$7 -> 0.33517135 | E9: =$E$8/$E$7 -> 0.60863581 | F9: =$F$8/$F$7 -> 0.72771555 | G9: =$G$8/$G$7 -> 0.93548077 | H9: =$H$8/$H$7 -> 1.2570584 | I9: =$I$8/$I$7 -> 1.394196 | J9: =$J$8/$J$7 -> 1.5603108 | K9: =$K$8/$K$7 -> 1.7298701 | L9: =$L$8/$L$7 -> 1.7830832 | M9: 売上÷損益分岐点売上（100%以上で黒字）
A10: 安全余裕率 | B10: 割合 | C10: =IF($C$8>$C$7,1-$C$7/$C$8,"─") -> ─ | D10: =IF($D$8>$D$7,1-$D$7/$D$8,"─") -> ─ | E10: =IF($E$8>$E$7,1-$E$7/$E$8,"─") -> ─ | F10: =IF($F$8>$F$7,1-$F$7/$F$8,"─") -> ─ | G10: =IF($G$8>$G$7,1-$G$7/$G$8,"─") -> ─ | H10: =IF($H$8>$H$7,1-$H$7/$H$8,"─") -> 0.20449201 | I10: =IF($I$8>$I$7,1-$I$7/$I$8,"─") -> 0.28274073 | J10: =IF($J$8>$J$7,1-$J$7/$J$8,"─") -> 0.35910206 | K10: =IF($K$8>$K$7,1-$K$7/$K$8,"─") -> 0.4219219 | L10: =IF($L$8>$L$7,1-$L$7/$L$8,"─") -> 0.43917366 | M10: (売上−分岐点売上)÷売上。赤字の年は「─」
A11: 人で見る
A12: 社員数 | B12: 人 | C12: ='体制と人件費'!$C$46 -> 5 | D12: ='体制と人件費'!$D$46 -> 8 | E12: ='体制と人件費'!$E$46 -> 12 | F12: ='体制と人件費'!$F$46 -> 18 | G12: ='体制と人件費'!$G$46 -> 23 | H12: ='体制と人件費'!$H$46 -> 24 | I12: ='体制と人件費'!$I$46 -> 27 | J12: ='体制と人件費'!$J$46 -> 29 | K12: ='体制と人件費'!$K$46 -> 30 | L12: ='体制と人件費'!$L$46 -> 32 | M12: 体制と人件費（採用連動の後）
A13: 期末の拠点 | B13: 拠点 | C13: ='拠点と売上'!$C$9 -> 3 | D13: ='拠点と売上'!$D$9 -> 12 | E13: ='拠点と売上'!$E$9 -> 29 | F13: ='拠点と売上'!$F$9 -> 53 | G13: ='拠点と売上'!$G$9 -> 81 | H13: ='拠点と売上'!$H$9 -> 109 | I13: ='拠点と売上'!$I$9 -> 136 | J13: ='拠点と売上'!$J$9 -> 162 | K13: ='拠点と売上'!$K$9 -> 186 | L13: ='拠点と売上'!$L$9 -> 207 | M13: 拠点と売上
A14: 社員1人あたりの拠点 | B14: 拠点/人 | C14: =$C$13/$C$12 -> 0.6 | D14: =$D$13/$D$12 -> 1.5 | E14: =$E$13/$E$12 -> 2.4166667 | F14: =$F$13/$F$12 -> 2.9444444 | G14: =$G$13/$G$12 -> 3.5217391 | H14: =$H$13/$H$12 -> 4.5416667 | I14: =$I$13/$I$12 -> 5.037037 | J14: =$J$13/$J$12 -> 5.5862069 | K14: =$K$13/$K$12 -> 6.2 | L14: =$L$13/$L$12 -> 6.46875 | M14: 期末の拠点÷社員数
A15: 社員1人あたりの販管費 | B15: 万円/人 | C15: =$C$5/$C$12 -> 1031.5 | D15: =$D$5/$D$12 -> 895.4375 | E15: =$E$5/$E$12 -> 787.09722 | F15: =$F$5/$F$12 -> 786.96296 | G15: =$G$5/$G$12 -> 752.72464 | H15: =$H$5/$H$12 -> 732.97222 | I15: =$I$5/$I$12 -> 740.65432 | J15: =$J$5/$J$12 -> 738.84483 | K15: =$K$5/$K$12 -> 744.74444 | L15: =$L$5/$L$12 -> 757.44271 | M15: 販管費÷社員数
A16: 社員1人あたりに要る課金拠点 | B16: 拠点/人 | C16: =$C$15/'値段と原価'!$C$15 -> 4.775463 | D16: =$D$15/'値段と原価'!$C$15 -> 4.145544 | E16: =$E$15/'値段と原価'!$C$15 -> 3.6439686 | F16: =$F$15/'値段と原価'!$C$15 -> 3.6433471 | G16: =$G$15/'値段と原価'!$C$15 -> 3.4848363 | H16: =$H$15/'値段と原価'!$C$15 -> 3.3933899 | I16: =$I$15/'値段と原価'!$C$15 -> 3.4289552 | J16: =$J$15/'値段と原価'!$C$15 -> 3.4205779 | K16: =$K$15/'値段と原価'!$C$15 -> 3.4478909 | L16: =$L$15/'値段と原価'!$C$15 -> 3.5066792 | M16: 社員1人の販管費÷1拠点の利用料の粗利（新規は初年度半額なので期末ではもっと要る）
A17: その年の体制で黒字に必要な拠点（通年で課金する拠点として）
A18: サービスの粗利 | B18: 万円/年 | C18: ='拠点と売上'!$C$21-'損益と現金'!$C$11-'損益と現金'!$C$12 -> 377 | D18: ='拠点と売上'!$D$21-'損益と現金'!$D$11-'損益と現金'!$D$12 -> 781 | E18: ='拠点と売上'!$E$21-'損益と現金'!$E$11-'損益と現金'!$E$12 -> 1428.6667 | F18: ='拠点と売上'!$F$21-'損益と現金'!$F$11-'損益と現金'!$F$12 -> 1776.3333 | G18: ='拠点と売上'!$G$21-'損益と現金'!$G$11-'損益と現金'!$G$12 -> 2263.6667 | H18: ='拠点と売上'!$H$21-'損益と現金'!$H$11-'損益と現金'!$H$12 -> 2457.3333 | I18: ='拠点と売上'!$I$21-'損益と現金'!$I$11-'損益と現金'!$I$12 -> 2608.6667 | J18: ='拠点と売上'!$J$21-'損益と現金'!$J$11-'損益と現金'!$J$12 -> 2760 | K18: ='拠点と売上'!$K$21-'損益と現金'!$K$11-'損益と現金'!$K$12 -> 2793.3333 | L18: ='拠点と売上'!$L$21-'損益と現金'!$L$11-'損益と現金'!$L$12 -> 2826.6667 | M18: 導入支援＋個社設定−導入支援の原価−個社設定の人件費
A19: 1拠点の利用料の粗利 | B19: 万円/年 | C19: ='値段と原価'!$C$15 -> 216 | D19: ='値段と原価'!$C$15 -> 216 | E19: ='値段と原価'!$C$15 -> 216 | F19: ='値段と原価'!$C$15 -> 216 | G19: ='値段と原価'!$C$15 -> 216 | H19: ='値段と原価'!$C$15 -> 216 | I19: ='値段と原価'!$C$15 -> 216 | J19: ='値段と原価'!$C$15 -> 216 | ... L19: ='値段と原価'!$C$15 -> 216 | M19: 値段と原価（300−84）
A20: 黒字に必要な課金拠点 | B20: 拠点 | C20: =($C$5-$C$18)/$C$19 -> 22.131944 | D20: =($D$5-$D$18)/$D$19 -> 29.548611 | E20: =($E$5-$E$18)/$E$19 -> 37.113426 | F20: =($F$5-$F$18)/$F$19 -> 57.356481 | G20: =($G$5-$G$18)/$G$19 -> 69.671296 | H20: =($H$5-$H$18)/$H$19 -> 70.064815 | I20: =($I$5-$I$18)/$I$19 -> 80.50463 | J20: =($J$5-$J$18)/$J$19 -> 86.418981 | K20: =($K$5-$K$18)/$K$19 -> 90.50463 | L20: =($L$5-$L$18)/$L$19 -> 99.127315 | M20: (販管費−サービスの粗利)÷216
A21: 実際の課金拠点（通年換算） | B21: 拠点 | C21: ='損益と現金'!$C$5 -> 0 | D21: ='損益と現金'!$D$5 -> 7.5 | E21: ='損益と現金'!$E$5 -> 20 | F21: ='損益と現金'!$F$5 -> 39.5 | G21: ='損益と現金'!$G$5 -> 64.5 | H21: ='損益と現金'!$H$5 -> 91 | I21: ='損益と現金'!$I$5 -> 117 | J21: ='損益と現金'!$J$5 -> 142 | K21: ='損益と現金'!$K$5 -> 166 | L21: ='損益と現金'!$L$5 -> 187 | M21: 損益と現金（1年目は試験導入なので0）
A22: 課金拠点の余裕（実際−必要） | B22: 拠点 | C22: =$C$21-$C$20 -> -22.131944 | D22: =$D$21-$D$20 -> -22.048611 | E22: =$E$21-$E$20 -> -17.113426 | F22: =$F$21-$F$20 -> -17.856481 | G22: =$G$21-$G$20 -> -5.1712963 | H22: =$H$21-$H$20 -> 20.935185 | I22: =$I$21-$I$20 -> 36.49537 | J22: =$J$21-$J$20 -> 55.581019 | K22: =$K$21-$K$20 -> 75.49537 | L22: =$L$21-$L$20 -> 87.872685 | M22: マイナス（赤）なら足りない
A23: 5年目に黒字にするのに必要な1拠点の台数（81拠点のまま台数だけ増やす）
A24: 課金する拠点（通年換算） | B24: 拠点 | C24: =INDEX($C$21:$L$21,1,'前提'!$E$148) -> 64.5 | D24: その年の (期首−解約)＋新規×半年
A25: 期末の拠点 | B25: 拠点 | C25: =INDEX($C$13:$L$13,1,'前提'!$E$148) -> 81
A26: 必要な利用料の粗利 | B26: 万円/年 | C26: =INDEX($C$5:$L$5,1,'前提'!$E$148)-INDEX($C$18:$L$18,1,'前提'!$E$148) -> 15049 | D26: 販管費−サービスの粗利
A27: 1拠点あたりに必要な利用料の粗利 | B27: 万円/年/拠点 | C27: =$C$26/$C$24 -> 233.31783 | D27: 必要な利用料の粗利÷課金する拠点
A28: 基盤の粗利（1拠点） | B28: 万円/年/拠点 | C28: ='値段と原価'!$C$5-'値段と原価'!$C$13 -> 48 | D28: 基盤60−データ基盤12
A29: 1台の粗利 | B29: 万円/年/台 | C29: ='値段と原価'!$C$6-'値段と原価'!$C$12 -> 16.8 | D29: 端末24−1台の原価7.2
A30: 必要な台数（計算） | B30: 台/拠点 | C30: =($C$27-$C$28)/$C$29 -> 11.030823 | D30: (1拠点に必要な粗利−基盤の粗利)÷1台の粗利
A31: 必要な台数（整数に切り上げ） | B31: 台/拠点 | C31: =ROUNDUP($C$30,0) -> 12 | D31: この台数なら5年目に黒字
A32: 確認：その台数での5年目の営業利益 | B32: 万円/年 | C32: =$C$24*($C$28+$C$29*$C$31)+INDEX($C$18:$L$18,1,'前提'!$E$148)-INDEX($C$5:$L$5,1,'前提'!$E$148) -> 1050.2 | D32: 課金する拠点×(基盤の粗利＋1台の粗利×台数)＋サービスの粗利−販管費
A33: 確認：1台少ない場合の5年目の営業利益 | B33: 万円/年 | C33: =$C$24*($C$28+$C$29*($C$31-1))+INDEX($C$18:$L$18,1,'前提'!$E$148)-INDEX($C$5:$L$5,1,'前提'!$E$148) -> -33.4 | D33: 同じ式で台数−1
A34: 確認：15台の場合の5年目の営業利益 | B34: 万円/年 | C34: =$C$24*($C$28+$C$29*'前提'!$E$149)+INDEX($C$18:$L$18,1,'前提'!$E$148)-INDEX($C$5:$L$5,1,'前提'!$E$148) -> 4301 | D34: 前提9-4の台数。tora_v2.js の1拠点15台（4,301万円）と同じになる
A35: 注：台数を増やしても、導入支援・人件費・データ基盤は変わらないとした（tora_v2.js と同じ）。
A36: 問い：黒字ラインは結局何台／何拠点？
A37: ="5年目（社員"&TEXT(INDEX($C$12:$L$12,1,'前提'!$E$148),"0")&"人・販管費"&TEXT(INDEX($C$5:$L$5,1,'前提'!$E$148),"#,##0")&"万円）で黒字にするには、通年で課金する拠点が"&TEXT(INDEX($C$20:$L$20,1,'前提'!$E$148),"0.0")&"拠点要る（実際は"&TEXT(INDEX($C$21:$L$21,1,'前提'!$E$148),"0.0")&"）。期末"&TEXT($C$25,"0")&"拠点のまま台数で越えるなら、1拠点"&TEXT($C$31,"0")&"台（計算では"&TEXT($C$30,"0.00")&"台）。10台のままなら"&IF(ISNUMBER('損益と現金'!$C$34),TEXT('損益と現金'!$C$34,"0")&"年目（期末"&TEXT(INDEX($C$13:$L$13,1,'損益と現金'!$C$34),"0")&"拠点・社員"&TEXT(INDEX($C$12:$L$12,1,'損益と現金'!$C$34),"0")&"人）に黒字。","10年以内には黒字にならない。") -> 5年目（社員23人・販管費17,313万円）で黒字にするには、通年で課金する拠点が69.7拠点要る（実際は64.5）。期末81拠点のまま台数で越えるなら、1拠点12台（計算では11.03台）。10台のままなら6年目（期末109拠点・社員24人）に黒字。

Sheet LTV・CAC
A1: LTV・CAC：LTVは控えめに7年で約1,571万円、CACは約86万円
A2: LTV＝1拠点の年の粗利×継続年数＋導入支援の粗利。CAC＝(営業の人件費＋広告)÷新規拠点（5年目）。tora_v2.js の unit() と同じ（計算詳細版 p.20）。
A3: 項目 | B3: 単位 | C3: 値 | F3: 式（言葉）
A4: LTV（1拠点が残す粗利）
A5: 1拠点の年の粗利 | B5: 万円/年 | C5: ='値段と原価'!$C$15 -> 216 | D5: 値段と原価（300−84）
A6: 導入支援の粗利 | B6: 万円/拠点 | C6: ='導入支援'!$C$21 -> 59 | D6: 導入支援（200−141）
A7: 計画の継続年数 | B7: 年 | C7: ='前提'!$E$146 -> 7 | D7: 前提9-1
A8: LTV（計画） | B8: 万円/拠点 | C8: =$C$5*$C$7+$C$6 -> 1571 | D8: 216×7年＋59
A9: 解約率から見た平均の継続年数 | B9: 年 | C9: =1/'拠点と売上'!$C$6 -> 10 | D9: 1÷解約率10%＝10年。7年は控えめ
A10: CAC（1拠点を獲得する費用）
A11: 計算する年 | B11: 年目 | C11: ='前提'!$E$147 -> 5 | D11: 前提9-2
A12: 営業の人数 | B12: 人 | C12: =INDEX('体制と人件費'!$C$19:$L$19,1,$C$11) -> 3 | D12: 体制と人件費（5年目3人）
A13: 営業の年収 | B13: 万円/年 | C13: =INDEX('体制と人件費'!$C$10:$L$10,1,$C$11) -> 650 | D13: 体制と人件費
A14: 営業の人件費 | B14: 万円/年 | C14: =$C$12*$C$13*'前提'!$E$109 -> 2340 | D14: 3人×650万円×1.2
A15: 広告・展示会 | B15: 万円/年 | C15: =INDEX('前提'!$E$127:$N$127,1,$C$11) -> 500 | D15: 前提7-10
A16: 新規拠点 | B16: 拠点/年 | C16: =INDEX('前提'!$E$118:$N$118,1,$C$11) -> 33 | D16: 前提7-1
A17: CAC | B17: 万円/拠点 | C17: =($C$14+$C$15)/$C$16 -> 86.060606 | D17: (営業3人×650万円×1.2＋広告500)÷新規33
A18: 回収月数 | B18: か月 | C18: =$C$17/($C$5/'前提'!$E$6) -> 4.7811448 | D18: CAC÷(1拠点の年の粗利÷12)
A19: LTV÷CAC（計画） | B19: 倍 | C19: =$C$8/$C$17 -> 18.254577 | D19: LTV÷CAC
A20: 継続年数を変えたら
A21: 継続年数 | B21: 単位 | C21: LTV（万円/拠点） | D21: LTV÷CAC（倍） | E21: 式（言葉）
A22: ='前提'!$E$151 -> 3 | B22: 万円・倍 | C22: =$C$5*'前提'!$E$151+$C$6 -> 707 | D22: =($C$5*'前提'!$E$151+$C$6)/$C$17 -> 8.2151408 | E22: 216×継続年数＋59、それをCACで割る
A23: ='前提'!$F$151 -> 5 | B23: 万円・倍 | C23: =$C$5*'前提'!$F$151+$C$6 -> 1139 | D23: =($C$5*'前提'!$F$151+$C$6)/$C$17 -> 13.234859 | E23: 216×継続年数＋59、それをCACで割る
A24: ='前提'!$G$151 -> 7 | B24: 万円・倍 | C24: =$C$5*'前提'!$G$151+$C$6 -> 1571 | D24: =($C$5*'前提'!$G$151+$C$6)/$C$17 -> 18.254577 | E24: 216×継続年数＋59、それをCACで割る
A25: ='前提'!$H$151 -> 10 | B25: 万円・倍 | C25: =$C$5*'前提'!$H$151+$C$6 -> 2219 | D25: =($C$5*'前提'!$H$151+$C$6)/$C$17 -> 25.784155 | E25: 216×継続年数＋59、それをCACで割る
A26: 獲得が難しくなったら（CACが増えた場合）
A27: CACの倍率 | B27: 単位 | C27: CAC（万円/拠点） | D27: LTV÷CAC（倍・計画の年数） | E27: 回収月数（か月） | F27: 式（言葉）
